Workbook

Sheet Summary
I1: 6 | J1: 100
B2: Account Manager :-- | C2: Amit Gandhi | I2: 100000 | J2: =(I2*J1)/I1 -> 1666666.7 | K2: =29650*12 -> 355800 | L2: =K2+J2 -> 2022466.7
E4: 4 | F4: [--- need to cange the respective month (Jan- 1, Feb- 2, Mar -3)
B5: Top Line Target 2026 | C5: 11449233 | D5: GP Target 2026 | E5: 8085686 | F5: NP Target 2026 | G5: 1959079 | H5: {-- enter your targets
B6: YTD Target | C6: =C5/12*E4 -> 3816411 | D6: YTD Target | E6: =E5/12*E4 -> 2695228.7 | F6: YTD Target | G6: =G5/12*E4 -> 653026.33
B7: Acheived Till Date (previous month) | C7: =SUM(H14:H16) -> 3349251.3 | D7: Acheived Till Date (previous month) | E7: =SUM(L14:L16) -> 2052120 | F7: Acheived Till Date (previous month) | G7: =SUM(Q14:Q16) -> 395614.75
B8: Current Month Forecast | C8: =H17 -> 1066082.3 | D8: Current Month Forecast | E8: =L17 -> 673493.16 | F8: Current Month Forecast | G8: =Q17 -> 109925.89
B9: Delta | C9: =(C8+C7)-C6 -> 598922.61 | D9: Delta | E9: =(E8+E7)-E6 -> 30384.514 | F9: Delta | G9: =(G8+G7)-G6 -> -147485.69
B10: Delta in % | C10: =C9/C6 -> 0.15693347 | D10: Delta in % | E10: =E9/E6 -> 0.011273446 | F10: Delta in % | G10: =G9/G6 -> -0.22584953
B12: Booking details | F12: Billing details
C13: Top Line | D13: GP Value | E13: NP Value | G13: Top Line Target | H13: Top Line Billing | I13: Top Line YTD Delta | J13: Top Line YTD Variance | K13: GP Target | L13: GP Billing | M13: GP YTD Delta | N13: YTD Variance % | P13: NP Target | Q13: NP Billing | R13: NP YTD Delta | S13: YTD Variance % | V13: Payroll Cost | W13: Total GP Value
B14: 46023 | C14: =SUMIF('Booking & Billing Forecast'!O:O,Summary!B:B,'Booking & Billing Forecast'!G:G) -> 914900 | D14: =SUMIF('Booking & Billing Forecast'!O:O,Summary!B:B,'Booking & Billing Forecast'!I:I) -> 914900 | E14: =SUMIF('Booking & Billing Forecast'!O:O,Summary!B:B,'Booking & Billing Forecast'!M:M) -> 260020 | F14: 46023 | G14: =C5/12*1 -> 954102.75 | H14: =SUM('Booking & Billing Forecast'!Q:Q) -> 1441947.4 | I14: =H14-G14 -> 487844.68 | J14: =I14/G14 -> 0.51131252 | K14: =E5/12*1 -> 673807.17 | L14: =SUM('Booking & Billing Forecast'!R:R) -> 385468.34 | M14: =L14-K14 -> -288338.83 | N14: =M14/K14 -> -0.42792484 | P14: =G5/12*1 -> 163256.58 | Q14: =SUM('Booking & Billing Forecast'!S:S) -> 122159.74 | R14: =Q14-P14 -> -41096.843 | S14: =R14/P14 -> -0.25173161 | V14: 268227 | W14: =V14+Q14 -> 390386.74
B15: 46054 | C15: =SUMIF('Booking & Billing Forecast'!O:O,Summary!B:B,'Booking & Billing Forecast'!G:G) -> 1357381.7 | D15: =SUMIF('Booking & Billing Forecast'!O:O,Summary!B:B,'Booking & Billing Forecast'!I:I) -> 552267.95 | E15: =SUMIF('Booking & Billing Forecast'!O:O,Summary!B:B,'Booking & Billing Forecast'!M:M) -> 106273.97 | F15: 46054 | G15: =C5/12*2 -> 1908205.5 | H15: =SUM('Booking & Billing Forecast'!T:T) -> 1227211.5 | I15: =SUM(H14:H15)-G15 -> 760953.45 | J15: =I15/G15 -> 0.39877961 | K15: =E5/12*2 -> 1347614.3 | L15: =SUM('Booking & Billing Forecast'!U:U) -> 1016686.3 | M15: =SUM(L14:L15)-K15 -> 54540.277 | N15: =M15/K15 -> 0.040471725 | P15: =G5/12*2 -> 326513.17 | Q15: =SUM('Booking & Billing Forecast'!V:V) -> 156474.24 | R15: =SUM(Q14:Q15)-P15 -> -47879.187 | S15: =R15/P15 -> -0.14663784 | V15: 853720 | W15: =V15+Q15 -> 1010194.2
B16: 46082 | C16: =SUMIF('Booking & Billing Forecast'!O:O,Summary!B:B,'Booking & Billing Forecast'!G:G) -> 1149449.3 | D16: =SUMIF('Booking & Billing Forecast'!O:O,Summary!B:B,'Booking & Billing Forecast'!I:I) -> 1146609.3 | E16: =SUMIF('Booking & Billing Forecast'!O:O,Summary!B:B,'Booking & Billing Forecast'!M:M) -> 149834.84 | F16: 46082 | G16: =C5/12*3 -> 2862308.2 | H16: =SUM('Booking & Billing Forecast'!W:W) -> 680092.32 | I16: =SUM(H14:H16)-G16 -> 486943.02 | J16: =I16/G16 -> 0.1701225 | K16: =E5/12*3 -> 2021421.5 | L16: =SUM('Booking & Billing Forecast'!X:X) -> 649965.41 | M16: =SUM(L14:L16)-K16 -> 30698.52 | N16: =M16/K16 -> 0.0151866 | P16: =G5/12*3 -> 489769.75 | Q16: =SUM('Booking & Billing Forecast'!Y:Y) -> 116980.77 | R16: =SUM(Q14:Q16)-P16 -> -94155 | S16: =R16/P16 -> -0.1922434 | T16: Q1
B17: 46113 | C17: =SUMIF('Booking & Billing Forecast'!O:O,Summary!B:B,'Booking & Billing Forecast'!G:G) -> 1309877.8 | D17: =SUMIF('Booking & Billing Forecast'!O:O,Summary!B:B,'Booking & Billing Forecast'!I:I) -> 146283.46 | E17: =SUMIF('Booking & Billing Forecast'!O:O,Summary!B:B,'Booking & Billing Forecast'!M:M) -> 73141.732 | F17: 46113 | G17: =C5/12*4 -> 3816411 | H17: =SUM('Booking & Billing Forecast'!Z:Z) -> 1066082.3 | I17: =SUM(H14:H17)-G17 -> 598922.61 | J17: =I17/G17 -> 0.15693347 | K17: =E5/12*4 -> 2695228.7 | L17: =SUM('Booking & Billing Forecast'!AA:AA) -> 673493.16 | M17: =SUM(L14:L17)-K17 -> 30384.514 | N17: =M17/K17 -> 0.011273446 | P17: =G5/12*4 -> 653026.33 | Q17: =SUM('Booking & Billing Forecast'!AB:AB) -> 109925.89 | R17: =SUM(Q14:Q17)-P17 -> -147485.69 | S17: =R17/P17 -> -0.22584953
B18: 46143 | C18: =SUMIF('Booking & Billing Forecast'!O:O,Summary!B:B,'Booking & Billing Forecast'!G:G) -> 1694431.2 | D18: =SUMIF('Booking & Billing Forecast'!O:O,Summary!B:B,'Booking & Billing Forecast'!I:I) -> 1398367.2 | E18: =SUMIF('Booking & Billing Forecast'!O:O,Summary!B:B,'Booking & Billing Forecast'!M:M) -> 189603.6 | F18: 46143 | G18: =C5/12*5 -> 4770513.8 | H18: =SUM('Booking & Billing Forecast'!AC:AC) -> 1339802.3 | I18: =SUM(H14:H18)-G18 -> 984622.16 | J18: =I18/G18 -> 0.20639751 | K18: =E5/12*5 -> 3369035.8 | L18: =SUM('Booking & Billing Forecast'!AD:AD) -> 637489.99 | M18: =SUM(L14:L18)-K18 -> -5932.6589 | N18: =M18/K18 -> -0.0017609367 | P18: =G5/12*5 -> 816282.92 | Q18: =SUM('Booking & Billing Forecast'!AE:AE) -> 96729.341 | R18: =SUM(Q14:Q18)-P18 -> -214012.93 | S18: =R18/P18 -> -0.26217985
B19: 46174 | C19: =SUMIF('Booking & Billing Forecast'!O:O,Summary!B:B,'Booking & Billing Forecast'!G:G) -> 1426344.4 | D19: =SUMIF('Booking & Billing Forecast'!O:O,Summary!B:B,'Booking & Billing Forecast'!I:I) -> 1426344.4 | E19: =SUMIF('Booking & Billing Forecast'!O:O,Summary!B:B,'Booking & Billing Forecast'!M:M) -> 143319.08 | F19: 46174 | G19: =C5/12*6 -> 5724616.5 | H19: =SUM('Booking & Billing Forecast'!AF:AF) -> 944579.46 | I19: =SUM(H14:H19)-G19 -> 975098.87 | J19: =I19/G19 -> 0.17033436 | K19: =E5/12*6 -> 4042843 | L19: =SUM('Booking & Billing Forecast'!AG:AG) -> 686531.72 | M19: =SUM(L14:L19)-K19 -> 6791.8908 | N19: =M19/K19 -> 0.0016799789 | P19: =G5/12*6 -> 979539.5 | Q19: =SUM('Booking & Billing Forecast'!AH:AH) -> 121247.7 | R19: =SUM(Q14:Q19)-P19 -> -256021.81 | S19: =R19/P19 -> -0.26136957 | T19: Q2
B20: 46204 | C20: =SUMIF('Booking & Billing Forecast'!O:O,Summary!B:B,'Booking & Billing Forecast'!G:G) -> 816653.05 | D20: =SUMIF('Booking & Billing Forecast'!O:O,Summary!B:B,'Booking & Billing Forecast'!I:I) -> 67009.314 | E20: =SUMIF('Booking & Billing Forecast'!O:O,Summary!B:B,'Booking & Billing Forecast'!M:M) -> 33504.657 | F20: 46204 | G20: =C5/12*7 -> 6678719.2 | H20: =SUM('Booking & Billing Forecast'!AI:AI) -> 675827.78 | I20: =SUM(H14:H20)-G20 -> 696823.9 | J20: =I20/G20 -> 0.10433496 | K20: =E5/12*7 -> 4716650.2 | L20: =SUM('Booking & Billing Forecast'!AJ:AJ) -> 574960.37 | M20: =SUM(L14:L20)-K20 -> -92054.904 | N20: =M20/K20 -> -0.019517009 | P20: =G5/12*7 -> 1142796.1 | Q20: =SUM('Booking & Billing Forecast'!AK:AK) -> 79934.765 | R20: =SUM(Q14:Q20)-P20 -> -339343.63 | S20: =R20/P20 -> -0.29694154
B21: 46235 | C21: =SUMIF('Booking & Billing Forecast'!O:O,Summary!B:B,'Booking & Billing Forecast'!G:G) -> 0 | D21: =SUMIF('Booking & Billing Forecast'!O:O,Summary!B:B,'Booking & Billing Forecast'!I:I) -> 0 | E21: =SUMIF('Booking & Billing Forecast'!O:O,Summary!B:B,'Booking & Billing Forecast'!M:M) -> 0 | F21: 46235 | G21: =C5/12*8 -> 7632822 | H21: =SUM('Booking & Billing Forecast'!AL:AL) -> 340333.29 | I21: =SUM(H14:H21)-G21 -> 83054.438 | J21: =I21/G21 -> 0.010881223 | K21: =E5/12*8 -> 5390457.3 | L21: =SUM('Booking & Billing Forecast'!AM:AM) -> 239574.88 | M21: =SUM(L14:L21)-K21 -> -526287.19 | N21: =M21/K21 -> -0.097633124 | P21: =G5/12*8 -> 1306052.7 | Q21: =SUM('Booking & Billing Forecast'!AN:AN) -> 43466.441 | R21: =SUM(Q14:Q21)-P21 -> -459133.77 | S21: =R21/P21 -> -0.35154308
B22: 46266 | C22: =SUMIF('Booking & Billing Forecast'!O:O,Summary!B:B,'Booking & Billing Forecast'!G:G) -> 0 | D22: =SUMIF('Booking & Billing Forecast'!O:O,Summary!B:B,'Booking & Billing Forecast'!I:I) -> 0 | E22: =SUMIF('Booking & Billing Forecast'!O:O,Summary!B:B,'Booking & Billing Forecast'!M:M) -> 0 | F22: 46266 | G22: =C5/12*9 -> 8586924.8 | H22: =SUM('Booking & Billing Forecast'!AO:AO) -> 331693.29 | I22: =SUM(H14:H22)-G22 -> -539355.02 | J22: =I22/G22 -> -0.062811197 | K22: =E5/12*9 -> 6064264.5 | L22: =SUM('Booking & Billing Forecast'!AP:AP) -> 238883.68 | M22: =SUM(L14:L22)-K22 -> -961210.67 | N22: =M22/K22 -> -0.15850408 | P22: =G5/12*9 -> 1469309.2 | Q22: =SUM('Booking & Billing Forecast'!AQ:AQ) -> 43120.841 | R22: =SUM(Q14:Q22)-P22 -> -579269.52 | S22: =R22/P22 -> -0.39424615 | T22: Q3
B23: 46296 | C23: =SUMIF('Booking & Billing Forecast'!O:O,Summary!B:B,'Booking & Billing Forecast'!G:G) -> 0 | D23: =SUMIF('Booking & Billing Forecast'!O:O,Summary!B:B,'Booking & Billing Forecast'!I:I) -> 0 | E23: =SUMIF('Booking & Billing Forecast'!O:O,Summary!B:B,'Booking & Billing Forecast'!M:M) -> 0 | F23: 46296 | G23: =C5/12*10 -> 9541027.5 | H23: =SUM('Booking & Billing Forecast'!AR:AR) -> 495059 | I23: =SUM(H14:H23)-G23 -> -998398.77 | J23: =I23/G23 -> -0.10464269 | K23: =E5/12*10 -> 6738071.7 | L23: =SUM('Booking & Billing Forecast'!AS:AS) -> 237173.9 | M23: =SUM(L14:L23)-K23 -> -1397843.9 | N23: =M23/K23 -> -0.2074546 | P23: =G5/12*10 -> 1632565.8 | Q23: =SUM('Booking & Billing Forecast'!AT:AT) -> 45832.857 | R23: =SUM(Q14:Q23)-P23 -> -696693.24 | S23: =R23/P23 -> -0.42674741
B24: 46327 | C24: =SUMIF('Booking & Billing Forecast'!O:O,Summary!B:B,'Booking & Billing Forecast'!G:G) -> 0 | D24: =SUMIF('Booking & Billing Forecast'!O:O,Summary!B:B,'Booking & Billing Forecast'!I:I) -> 0 | E24: =SUMIF('Booking & Billing Forecast'!O:O,Summary!B:B,'Booking & Billing Forecast'!M:M) -> 0 | F24: 46327 | G24: =C5/12*11 -> 10495130 | H24: =SUM('Booking & Billing Forecast'!AU:AU) -> 149000 | I24: =SUM(H14:H24)-G24 -> -1803501.5 | J24: =I24/G24 -> -0.17184175 | K24: =E5/12*11 -> 7411878.8 | L24: =SUM('Booking & Billing Forecast'!AV:AV) -> 149000 | M24: =SUM(L14:L24)-K24 -> -1922651.1 | N24: =M24/K24 -> -0.25940131 | P24: =G5/12*11 -> 1795822.4 | Q24: =SUM('Booking & Billing Forecast'!AW:AW) -> 16422 | R24: =SUM(Q14:Q24)-P24 -> -843527.83 | S24: =R24/P24 -> -0.46971673
B25: 46357 | C25: =SUMIF('Booking & Billing Forecast'!O:O,Summary!B:B,'Booking & Billing Forecast'!G:G) -> 0 | D25: =SUMIF('Booking & Billing Forecast'!O:O,Summary!B:B,'Booking & Billing Forecast'!I:I) -> 0 | E25: =SUMIF('Booking & Billing Forecast'!O:O,Summary!B:B,'Booking & Billing Forecast'!M:M) -> 0 | F25: 46357 | G25: =C5/12*12 -> 11449233 | H25: =SUM('Booking & Billing Forecast'!AX:AX) -> 396706.85 | I25: =SUM(H14:H25)-G25 -> -2360897.4 | J25: =I25/G25 -> -0.20620573 | K25: =E5/12*12 -> 8085686 | L25: =SUM('Booking & Billing Forecast'!AY:AY) -> 186624.9 | M25: =SUM(L14:L25)-K25 -> -2409833.4 | N25: =M25/K25 -> -0.29803697 | P25: =G5/12*12 -> 1959079 | Q25: =SUM('Booking & Billing Forecast'!AZ:AZ) -> 35234.451 | R25: =SUM(Q14:Q25)-P25 -> -971549.96 | S25: =R25/P25 -> -0.49592179 | T25: Q4
C26: =SUM(C14:C25) -> 8669037.5 | D26: =SUM(D14:D25) -> 5651781.6 | E26: =SUM(E14:E25) -> 955697.89 | H26: =SUM(H14:H25) -> 9088335.6 | L26: =SUM(L14:L25) -> 5675852.6 | Q26: =SUM(Q14:Q25) -> 987529.04
C27: =C26-C5 -> -2780195.5
B29: Opportunity Summary
B30: Opportunity Pipelines | C30: Top Line | D30: GP Value | E30: NP Value
B31: 0.8 | C31: =SUMIF('Opportunity Tracker'!L:L,Summary!B:B,'Opportunity Tracker'!H:H) -> 386417.81 | D31: =SUMIF('Opportunity Tracker'!L:L,Summary!B:B,'Opportunity Tracker'!J:J) -> 316524.53 | E31: =SUMIF('Opportunity Tracker'!L:L,Summary!B:B,'Opportunity Tracker'!K:K) -> 114262.26 | F31: Note to Pavi - As per Amit, will book and bill 100% Dec 2026 @ 45,850.56
B32: 0.5 | C32: =SUMIF('Opportunity Tracker'!L:L,Summary!B:B,'Opportunity Tracker'!H:H) -> 19792061 | D32: =SUMIF('Opportunity Tracker'!L:L,Summary!B:B,'Opportunity Tracker'!J:J) -> 5848534.5 | E32: =SUMIF('Opportunity Tracker'!L:L,Summary!B:B,'Opportunity Tracker'!K:K) -> 2924267.2 | F32: Note to Pavi - As per Amit, will book and bill 100% Dec 2026 @ 61,662.28
B33: 0.4 | C33: =SUMIF('Opportunity Tracker'!L:L,Summary!B:B,'Opportunity Tracker'!H:H) -> 26020.8 | D33: =SUMIF('Opportunity Tracker'!L:L,Summary!B:B,'Opportunity Tracker'!J:J) -> 5204.16 | E33: =SUMIF('Opportunity Tracker'!L:L,Summary!B:B,'Opportunity Tracker'!K:K) -> 2602.08
B34: Lost | C34: =SUMIF('Opportunity Tracker'!L:L,Summary!B:B,'Opportunity Tracker'!H:H) -> 434656.46 | D34: =SUMIF('Opportunity Tracker'!L:L,Summary!B:B,'Opportunity Tracker'!J:J) -> 72633.823 | E34: =SUMIF('Opportunity Tracker'!L:L,Summary!B:B,'Opportunity Tracker'!K:K) -> 36116.912
B35: Hold | C35: =SUMIF('Opportunity Tracker'!L:L,Summary!B:B,'Opportunity Tracker'!H:H) -> 0 | D35: =SUMIF('Opportunity Tracker'!L:L,Summary!B:B,'Opportunity Tracker'!J:J) -> 0 | E35: =SUMIF('Opportunity Tracker'!L:L,Summary!B:B,'Opportunity Tracker'!K:K) -> 0
B36: Didn’t Participate | C36: =SUMIF('Opportunity Tracker'!L:L,Summary!B:B,'Opportunity Tracker'!H:H) -> 150000 | D36: =SUMIF('Opportunity Tracker'!L:L,Summary!B:B,'Opportunity Tracker'!J:J) -> 30000 | E36: =SUMIF('Opportunity Tracker'!L:L,Summary!B:B,'Opportunity Tracker'!K:K) -> 15000
B37: Won Yet to be Booked in Vikas | C37: =SUMIF('Opportunity Tracker'!L:L,Summary!B:B,'Opportunity Tracker'!H:H) -> 0 | D37: =SUMIF('Opportunity Tracker'!L:L,Summary!B:B,'Opportunity Tracker'!J:J) -> 0 | E37: =SUMIF('Opportunity Tracker'!L:L,Summary!B:B,'Opportunity Tracker'!K:K) -> 0
B40: Committed | C40: Top Line | D40: GP Value | E40: NP Value
B41: Till March 2026 | C41: =SUM(H14:H16) -> 3349251.3 | D41: =SUM(L14:L16) -> 2052120 | E41: =SUM(Q14:Q16) -> 395614.75
B42: April to Dec | C42: 5512521 | D42: 3654845 | E42: 607890
B43: Amit 80% | C43: 426602.76 | D43: 99988.17 | E43: 45705.18
B44: Amit 50% | C44: 676371.52 | D44: 139022.12 | E44: 69511.06
C46: =SUM(C41:C45) -> 9964746.6 | D46: =SUM(D41:D45) -> 5945975.3 | E46: =SUM(E41:E45) -> 1118721
...

Sheet Booking & Billing Forecast
A1: Date | B1: Account Manager | C1: Billing Division | D1: Customer | E1: Project Description | F1: Project Type | G1: Order Value | H1: GP% | I1: GP Value | J1: Internal Team involved | K1: Payroll % | L1: Payroll Cost | M1: NP Value | N1: Status | O1: Booking Month | P1: Vikas Invoice | Q1: Jan-26 | T1: Feb-26 | W1: Mar-26 | Z1: Apr-26 | AC1: May-26 | AF1: Jun-26 | AI1: Jul-26 | AL1: Aug-26 | AO1: Sept-26 | AR1: Oct-26 | AU1: Nov-26 | AX1: Dec-26
Q2: Invoice Value | R2: GP | S2: NP Value | T2: Invoice Value | U2: GP | V2: NP Value | W2: Invoice Value | X2: GP | Y2: NP Value | Z2: Invoice Value | AA2: GP | AB2: NP Value | AC2: Invoice Value | AD2: GP | AE2: NP Value | AF2: Invoice Value | AG2: GP | AH2: NP Value | AI2: Invoice Value | AJ2: GP | AK2: NP Value | AL2: Invoice Value | AM2: GP | AN2: NP Value | AO2: Invoice Value | AP2: GP | AQ2: NP Value | AR2: Invoice Value | AS2: GP | AT2: NP Value | AU2: Invoice Value | AV2: GP | AW2: NP Value | AX2: Invoice Value | AY2: GP | AZ2: NP Value
D3: Financial Costing | S3: =-524.58+5477.11-41.13 -> 4911.4 | V3: =-227.02-15.01 -> -242.03 | Y3: =-2622.44+0.8 -> -2621.64 | AB3: 599.52
B4: Amit Gandhi | C4: MSDT | D4: Dollar Rent A Car | E4: Azure Cloud Usage (LPO # 24000028/L2/00060) | F4: Cloud | G4: 56904.6 | H4: 0.15122129 | I4: =H4*G4 -> 8605.1868 | J4: Yes | K4: 0.5 | L4: =I4*K4 -> 4302.5934 | M4: =I4-L4 -> 4302.5934 | N4: Booked in VIkas | O4: 2024 | P4: DCO2402246 | Q4: 196.32 | R4: =S4+8 -> 22.74 | S4: 14.74 | W4: 110.55 | X4: =Y4+8 -> 24.72 | Y4: 16.72 | Z4: 117.03 | AA4: =AB4+9 -> 17.73 | AB4: 8.73
B5: Amit Gandhi | C5: MSDT | D5: Dubai Furniture Manufacturing Co. LLC | E5: Azure Cloud Usage (LPO # 1003/L5) | F5: Cloud | G5: 49963 | H5: 0.08 | I5: =H5*G5 -> 3997.04 | J5: Yes | K5: 0.5 | L5: =I5*K5 -> 1998.52 | M5: =I5-L5 -> 1998.52 | N5: Booked in VIkas | O5: 2025 | P5: DCO2506584 | Q5: 12155.26 | R5: =S5+571 -> 1147.26 | S5: 576.26 | T5: 5022.84 | U5: =V5+182+15 -> 392.84 | V5: 195.84 | Z5: 5015.45 | AA5: =AB5+195 -> 391.45 | AB5: 196.45
A6: 45463 | B6: Amit Gandhi | C6: MSDT | D6: Emirates Post Group (7X) | E6: Digital Signature: DocuSign - 60000 Envelopes (Contract # 100057) | F6: Licenses | G6: 420120.54 | H6: 0.15340487 | I6: =G6*H6 -> 64448.538 | J6: No | L6: =I6*K6 -> 0 | M6: =I6-L6 -> 64448.538 | N6: Booked in VIkas | O6: 2024 | P6: DCO2407384 | T6: 137706.85 | U6: =V6+10587 -> 21173.6 | V6: 10586.6 | AX6: 137706.85 | AY6: =AX6*0.153404872524234 -> 21124.902 | AZ6: =AY6*50% -> 10562.451
B7: Amit Gandhi | C7: MSDT | D7: Arenco Real Estate Co LLC | E7: Windows Workload Migration - Azure cloud Usage for 24-25 (LPO # 24000090/OX) | F7: Cloud | G7: 2504127.5 | H7: 0.11258213 | I7: =H7*G7 -> 281920 | J7: Yes | K7: 0.5 | L7: =I7*K7 -> 140960 | M7: =I7-L7 -> 140960 | N7: Booked in VIkas | O7: 2025 | P7: DCO2406943
A8: 45689 | B8: Amit Gandhi | C8: MSDT | D8: Al Farwaniya Property Developments Limited | E8: Managed Services - EUS & Network Security | F8: Managed Services | G8: 162000 | H8: 1 | I8: =G8*H8 -> 162000 | J8: Yes | L8: 100801.27 | M8: =I8-L8 -> 61198.732 | N8: Booked in VIkas | O8: 2025 | P8: DMT2500030 | Q8: 14169 | R8: =Q8 -> 14169 | S8: 10060 | T8: 12462 | U8: =V8+9535 -> 12462 | V8: 2927 | W8: 13797 | X8: =Y8+10557 -> 13797 | Y8: 3240 | Z8: 6676 | AA8: =Z8 -> 6676 | AB8: 1567
A9: 45694 | B9: Amit Gandhi | C9: MSDT | D9: Emirates Post Group (7X) | E9: Managed Services - IT Helpdesk & Desktop Support: 2026 (Contract # 100122/2025) | F9: Managed Services | G9: =149000*3 -> 447000 | H9: 1 | I9: =G9*H9 -> 447000 | J9: No | L9: =G9*0.88 -> 393360 | M9: =I9-L9 -> 53640 | N9: Booked in VIkas | O9: 46054 | P9: DCO2504715 | Q9: 149000 | R9: =S9+132578 -> 149000 | S9: =Q9-132578 -> 16422 | T9: 149000 | U9: =V9+132201 -> 149000 | V9: 16799 | W9: 149000 | X9: =Y9+133615 -> 149000 | Y9: =W9-133615 -> 15385
A10: 45694 | B10: Amit Gandhi | C10: MSDT | D10: Emirates Post Group (7X) | E10: Managed Services - IT Helpdesk & Desktop Support: 2026 (Contract # 100122/2025) | F10: Managed Services | G10: =149000*9 -> 1341000 | H10: 1 | I10: =G10*H10 -> 1341000 | J10: No | L10: =G10*0.88 -> 1180080 | M10: =I10-L10 -> 160920 | N10: Booked in VIkas | O10: 46143 | P10: DCO2504715 | Z10: 149000 | AA10: =Z10 -> 149000 | AB10: =AA10-132578 -> 16422 | AC10: 149000 | AD10: =AC10 -> 149000 | AE10: =AD10-132578 -> 16422 | AF10: 149000 | AG10: =AF10 -> 149000 | AH10: =AG10-132578 -> 16422 | AI10: 149000 | AJ10: =AI10 -> 149000 | AK10: =AJ10-132578 -> 16422 | AL10: 149000 | AM10: =AL10 -> 149000 | AN10: =AM10-132578 -> 16422 | AO10: 149000 | AP10: =AO10 -> 149000 | AQ10: =AP10-132578 -> 16422 | AR10: 149000 | AS10: =AR10 -> 149000 | AT10: =AS10-132578 -> 16422 | AU10: 149000 | AV10: =AU10 -> 149000 | AW10: =AV10-132578 -> 16422 | AX10: 149000 | AY10: =AX10 -> 149000 | AZ10: =AY10-132578 -> 16422
A11: 45839 | B11: Amit Gandhi | C11: ELV | D11: Amlak Finance PJSC | E11: APC UPS AMC (LPO # 9856) | F11: AMC Alpha | G11: 7000 | H11: 1 | I11: =G11*H11 -> 7000 | J11: No | K11: 0.5 | L11: 3290 | M11: =I11-L11 -> 3710 | N11: Booked in VIkas | O11: 2025 | P11: DMT2500207 | Q11: 595 | R11: =S11+170 -> -138 | S11: -308 | T11: 537 | U11: =V11+153 -> 345 | V11: 192 | W11: 595 | X11: =Y11+170 -> 383 | Y11: 213 | Z11: 575 | AA11: =AB11+164 -> 72 | AB11: -92 | AC11: 595 | AD11: =AE11+170 -> 489 | AE11: 319 | AF11: 575 | AG11: =AH11+164 -> 472 | AH11: 308 | AI11: 613 | AJ11: =AK11+177 -> 504 | AK11: 327
A12: 45839 | B12: Amit Gandhi | C12: Micro | D12: National Bank of Ras Al Khaimah | E12: Exchange Upgrade 2016 to 2019 | F12: Microsoft | G12: 100000 | H12: 1 | I12: =G12*H12 -> 100000 | J12: Yes | K12: 0.5 | L12: =I12*K12 -> 50000 | M12: =I12-L12 -> 50000 | N12: Booked in VIkas | O12: 46023 | P12: DCO2508488 | AF12: 50000 | AG12: 50000 | AH12: 25000
A13: 45891 | B13: Amit Gandhi | C13: MSDT | D13: Amlak Finance PJSC | E13: Managed Services - IT Infrastructure - 2026 (LPO # 9987) | F13: Managed Services | G13: =977880/12*10 -> 814900 | H13: 1 | I13: =G13*H13 -> 814900 | J13: Yes | L13: =60488*10 -> 604880 | M13: =I13-L13 -> 210020 | N13: Booked in VIkas | O13: 46023 | P13: DCO2508313 | Q13: 81490 | R13: =Q13-3000 -> 78490 | S13: 21002 | T13: 81490 | U13: =V13+57488 -> 78490 | V13: 21002 | W13: 81490 | X13: =Y13+58463 -> 78490 | Y13: 20027 | Z13: 81490 | AA13: =Z13-3000 -> 78490 | AB13: 21002 | AC13: 81490 | AD13: =AC13-3000 -> 78490 | AE13: 21002 | AF13: 81490 | AG13: =AF13-3000 -> 78490 | AH13: 21002 | AI13: 81490 | AJ13: =AI13-3000 -> 78490 | AK13: 21002 | AL13: 81490 | AM13: =AL13-3000 -> 78490 | AN13: 21002 | AO13: 81490 | AP13: =AO13-3000 -> 78490 | AQ13: 21002 | AR13: 81490 | AS13: =AR13-3000 -> 78490 | AT13: 21002
A14: 45901 | B14: Amit Gandhi | C14: Micro | D14: Arenco Real Estate Co LLC | E14: O365 Backup on Veeam (LPO # 25000112) | F14: Micro | G14: 103680 | H14: 0.08 | I14: =G14*H14 -> 8294.4 | J14: No | K14: 0.5 | L14: =I14*K14 -> 4147.2 | M14: =I14-L14 -> 4147.2 | N14: Booked in VIkas | O14: 2025 | P14: DCO2507049 | Q14: =G14*50% -> 51840 | R14: =S14+2075 -> 4147.2 | S14: 2072.2 | Z14: =G14/12*3 -> 25920 | AA14: =I14/12*3 -> 2073.6 | AB14: =M14/12*3 -> 1036.8 | AC14: =G14/12 -> 8640 | AD14: =I14/12 -> 691.2 | AE14: =M14/12 -> 345.6 | AF14: =G14/12 -> 8640 | AG14: =I14/12 -> 691.2 | AH14: =M14/12 -> 345.6 | AI14: =G14/12 -> 8640 | AJ14: =I14/12 -> 691.2 | AK14: =M14/12 -> 345.6 | AL14: =G14/12 -> 8640 | AM14: =I14/12 -> 691.2 | AN14: =M14/12 -> 345.6
A15: 45912 | B15: Amit Gandhi | C15: Adnan / Thejas | D15: Thrifty Rent A Car | E15: Team Integration with Telephony System and Call Center (LPO # 26000017) | F15: Network | G15: 71600.002 | H15: 0.23609164 | I15: =G15*H15 -> 16904.162 | J15: Yes | K15: 0.5 | L15: =I15*K15 -> 8452.0811 | M15: =I15-L15 -> 8452.0811 | N15: Booked in VIkas | O15: 46204 | P15: DCO2601464 | AF15: =G15 -> 71600.002 | AG15: =I15 -> 16904.162 | AH15: =M15 -> 8452.0811
A16: 45952 | B16: Amit Gandhi | C16: Micro | D16: Marlin Interiors Design LLC | E16: NetApp Upgrade (LPO # 25000093/L5) | F16: Hardware | G16: 74568.05 | H16: 0.062243178 | I16: =G16*H16 -> 4641.3524 | J16: Yes | K16: 0.5 | L16: =I16*K16 -> 2320.6762 | M16: =I16-L16 -> 2320.6762 | N16: Booked in VIkas | O16: 46054 | P16: DCO2509184 | Q16: =G16 -> 74568.05 | R16: =S16+2320 -> 4640.76 | S16: 2320.76
A17: 45974 | B17: Amit Gandhi | C17: MSDT | D17: Amlak Finance PJSC | E17: BCP site (LPO # PO# 10018) | F17: Hardware | G17: 38274.652 | H17: 0.50999165 | I17: =G17*H17 -> 19519.753 | J17: Yes | K17: 0.5 | L17: =I17*K17 -> 9759.8764 | M17: =I17-L17 -> 9759.8764 | N17: Booked in VIkas | O17: 46054 | P17: DCO2509094 | Q17: 38274.652 | R17: =S17+9108 -> 19241.56 | S17: 10133.56
A18: 45974 | B18: Amit Gandhi | C18: Rajendran | D18: Emirates Post Group (7X) | E18: DocuSign SDFC Addon Licenses | F18: Licenses | G18: 2315.0203 | H18: 0.13607668 | I18: =G18*H18 -> 315.02028 | J18: No | K18: 0.5 | L18: =I18*K18 -> 157.51014 | M18: =I18-L18 -> 157.51014 | N18: Booked in VIkas | O18: 46082 | P18: DCO2601283 | Z18: =G18 -> 2315.0203 | AA18: =I18 -> 315.02028 | AB18: =M18 -> 157.51014
A19: 45980 | B19: Amit Gandhi | C19: Micro | D19: Department of Economy & Tourism | E19: DCT - Adobe License renewal (LPO# 42507074/0) | F19: Licenses | G19: 7757.88 | H19: =I19/G19 -> 0.1211465 | I19: 939.84 | J19: No | K19: 0.5 | L19: 388 | M19: =I19-L19 -> 551.84 | N19: Booked in VIkas | O19: 2025 | P19: DCO2509466 | Q19: 7757.88 | R19: =S19+388 -> 939.84 | S19: =M19 -> 551.84
A20: 46014 | B20: Amit Gandhi | C20: Rishabh | D20: Al Farwaniya Property Developments Limited | E20: Managed Services - Systems Support - Jan 2026 (LPO # 534) | F20: MSDT | G20: 12500 | H20: 1 | I20: =G20*H20 -> 12500 | J20: Yes | K20: 0.5 | L20: =I20*K20 -> 6250 | M20: =I20-L20 -> 6250 | N20: Booked in VIkas | O20: 46054 | P20: DCO2600593 | Q20: 12500 | R20: =Q20 -> 12500 | S20: =R20*30% -> 3750
A21: 46023 | B21: Amit Gandhi | C21: MSDT | D21: Arenco Real Estate Co LLC | E21: AVD Assessment | F21: Cloud | G21: 41971.43 | H21: 1 | I21: =H21*G21 -> 41971.43 | J21: Yes | K21: 0.2 | L21: =I21*K21 -> 8394.286 | M21: =I21-L21 -> 33577.144 | N21: Booked in VIkas | O21: 46082 | P21: DCO2500201 | W21: =G21 -> 41971.43 | X21: =Y21+8394 -> 41971.43 | Y21: 33577.43
A22: 46023 | B22: Amit Gandhi | C22: MSDT | D22: Department of Economy & Tourism | E22: Managed Services: Multiple IT Services 2026 (LPO # 42600429) | F22: Managed Services | G22: =(363820.96*3) -> 1091462.9 | H22: 1 | I22: =G22*H22 -> 1091462.9 | J22: No | L22: =G22*(1-12.56%) -> 954375.14 | M22: =(I22*12.56%)*80% -> 109670.19 | N22: Booked in VIkas | O22: 46082 | P22: DCO2601199 | T22: =363820.96*2 -> 727641.92 | U22: =V22+496250+140000 -> 727641.92 | V22: 91391.92 | W22: 363820.96 | X22: =Y22+318125 -> 363820.96 | Y22: 45695.96
A23: 46023 | B23: Amit Gandhi | C23: MSDT | D23: Department of Economy & Tourism | E23: Managed Services: Multiple IT Services 2026 (LPO # 42600429) | F23: Managed Services | G23: =(363820.96*3+334881.49) -> 1426344.4 | H23: 1 | I23: =G23*H23 -> 1426344.4 | J23: No | L23: =G23*(1-12.56%) -> 1247195.5 | M23: =(I23*12.56%)*80% -> 143319.08 | N23: Booked in VIkas | O23: 46174 | P23: DCO2601199 | Z23: 363820.96 | AA23: 363820.96 | AB23: 36141.324 | AC23: 363820.96 | AD23: 363820.96 | AE23: 36141.324 | AF23: 363820.96 | AG23: 363820.96 | AH23: 36141.324 | AI23: 334881.49 | AJ23: 334881.49 | AK23: 36141.324
A24: 46024 | B24: Amit Gandhi | C24: MSDT | D24: Data Hub Integrated Solutions Moro LLC | E24: Cyber 360 CR (LPO # 3224250888) | F24: BizApp | G24: 110000 | H24: 0.15 | I24: =H24*G24 -> 16500 | J24: No | K24: 0.5 | L24: =I24*K24 -> 8250 | M24: =I24-L24 -> 8250 | N24: Booked in VIkas | O24: 46204 | P24: DCO2600249 | AX24: =G24 -> 110000 | AY24: =I24 -> 16500 | AZ24: =M24 -> 8250
A25: 46024 | B25: Amit Gandhi | C25: MSDT | D25: Arenco Real Estate Co LLC | E25: Windows Workload Migration - Azure cloud Usage for 25-26 (LPO # 26000001) | F25: Cloud | G25: 1214439.5 | H25: 0.11258213 | I25: =H25*G25 -> 136724.18 | J25: Yes | K25: 0.5 | L25: =I25*K25 -> 68362.092 | M25: =I25-L25 -> 68362.092 | N25: Booked in VIkas | O25: 46113 | P25: DCO2600233 | Q25: 246606.28 | R25: =S25+17855 -> 35708.28 | S25: 17853.28 | T25: 94775.91 | U25: =V25+6375+102 -> 12955.91 | V25: 6478.91 | Z25: 102471.84 | AA25: =AB25+14270.84 -> 21407.68 | AB25: 7136.84 | AC25: =G25/12 -> 101203.29 | AD25: =I25/12 -> 11393.682 | AE25: =M25/12 -> 5696.841 | AF25: =G25/12 -> 101203.29 | AG25: =I25/12 -> 11393.682 | AH25: =M25/12 -> 5696.841 | AI25: =G25/12 -> 101203.29 | AJ25: =I25/12 -> 11393.682 | AK25: =M25/12 -> 5696.841 | AL25: =G25/12 -> 101203.29 | AM25: =I25/12 -> 11393.682 | AN25: =M25/12 -> 5696.841 | AO25: =G25/12 -> 101203.29 | AP25: =I25/12 -> 11393.682 | AQ25: =M25/12 -> 5696.841 | AR25: =(G25-(SUM(Q25+T25+W25+Z25+AC25+AF25+AI25+AL25+AO25))) -> 264569 | AS25: =(I25-(SUM(R25+U25+X25+AA25+AD25+AG25+AJ25+AM25+AP25))) -> 9683.9036 | AT25: =(M25-(SUM(S25+V25+Y25+AB25+AE25+AH25+AK25+AN25+AQ25))) -> 8408.8568
A26: 46024 | B26: Amit Gandhi | C26: MSDT | D26: Arenco Real Estate Co LLC | E26: Windows Workload Migration - License renewal (LPO # 26000002) | F26: Cloud | G26: 752794.99 | H26: 0.08714152 | I26: =H26*G26 -> 65599.7 | J26: Yes | K26: 0.5 | L26: =I26*K26 -> 32799.85 | M26: =I26-L26 -> 32799.85 | N26: Booked in VIkas | O26: 46054 | P26: DCO2600261 | Q26: =G26 -> 752794.99 | R26: =S26+32800 -> 65599.7 | S26: 32799.7
A27: 46030 | B27: Amit Gandhi | C27: NW | D27: Amlak Finance PJSC | E27: Cisco Renewal (LPO # 10261) | F27: Network | G27: 235181.04 | H27: 0.17691683 | I27: =H27*G27 -> 41607.483 | J27: No | K27: 0.5 | L27: =I27*K27 -> 20803.742 | M27: =I27-L27 -> 20803.742 | N27: Booked in VIkas | O27: 46143 | P27: DCO2602509 | Z27: =G27 -> 235181.04 | AA27: =AB27+20804 -> 41878.72 | AB27: 21074.72
A28: 46034 | B28: Amit Gandhi | C28: ELV | D28: Al Farwaniya Property Developments Limited | E28: Biometric machine (LPO # 540) | F28: ELV | G28: 4875 | H28: 0.28 | I28: =H28*G28 -> 1365 | J28: Yes | K28: 0.5 | L28: =I28*K28 -> 682.5 | M28: =I28-L28 -> 682.5 | N28: Booked in VIkas | O28: 46054 | P28: DCO2600620 | T28: =G28 -> 4875 | U28: =V28+682 -> 1365 | V28: 683
A29: 46036 | B29: Amit Gandhi | C29: Rajendran / Kumar | D29: Arenco Real Estate Co LLC | E29: File Server Migration (LPO # 26000026) | F29: Hardware | G29: 635053.04 | H29: 0.052917079 | I29: =H29*G29 -> 33605.152 | J29: Yes | K29: 0.5 | L29: =I29*K29 -> 16802.576 | M29: =I29-L29 -> 16802.576 | N29: Booked in VIkas | O29: 46204 | P29: DCO2601512 | AC29: =G29 -> 635053.04 | AD29: =I29 -> 33605.152 | AE29: =M29 -> 16802.576
A30: 46048 | B30: Amit Gandhi | C30: Rishabh | D30: Al Farwaniya Property Developments Limited | E30: Managed Services - Systems Support - Feb 2026 (LPO # 553) | F30: MSDT | G30: 12500 | H30: 1 | I30: =G30*H30 -> 12500 | J30: Yes | K30: 0.5 | L30: =I30*K30 -> 6250 | M30: =I30-L30 -> 6250 | N30: Booked in VIkas | O30: 46082 | P30: DCO2601531 | T30: =G30 -> 12500 | U30: =V30+6250 -> 12500 | V30: =M30 -> 6250
A31: 46049 | B31: Amit Gandhi | C31: Micro | D31: Nutricia Middle East DMCC | E31: Labelling Machine Tapes (LPO # 4505925418) | F31: Micro | G31: =60*20 -> 1200 | H31: 0.3 | I31: =H31*G31 -> 360 | J31: No | K31: 0.5 | L31: =I31*K31 -> 180 | M31: =I31-L31 -> 180 | N31: Booked in VIkas | O31: 46082 | P31: DCO2600942 | T31: =G31 -> 1200 | U31: =V31+150 -> 360 | V31: 210
A32: 46055 | B32: Amit Gandhi | C32: Micro | D32: Arenco Real Estate Co LLC | E32: Veeam Server Instance Renewal (LPO # 26000021) | F32: Licenses | G32: 27369.021 | H32: 0.06 | I32: =H32*G32 -> 1642.1413 | J32: No | K32: 0.5 | L32: =I32*K32 -> 821.07064 | M32: =I32-L32 -> 821.07064 | N32: Booked in VIkas | O32: 46054 | P32: DCO2601352 | W32: =G32 -> 27369.021 | X32: =Y32+821 -> 2059.02 | Y32: 1238.02
A33: 46065 | B33: Amit Gandhi | C33: NW | D33: Arenco Real Estate Co LLC | E33: Business Continuity (LPO # 2600044) | F33: Licenses | G33: 118250.21 | H33: 0.13327429 | I33: =H33*G33 -> 15759.712 | J33: No | K33: 0.5 | L33: =I33*K33 -> 7879.8561 | M33: =I33-L33 -> 7879.8561 | N33: Booked in VIkas | O33: 46143 | AF33: =G33 -> 118250.21 | AG33: =I33 -> 15759.712 | AH33: =M33 -> 7879.8561
A34: 46072 | B34: Amit Gandhi | C34: NW | D34: Arenco Real Estate Co LLC | E34: Fortinet 50G Firewall - 50 Units (LPO # 26000038) | F34: Hardware | G34: 93500 | H34: 0.1 | I34: =H34*G34 -> 9350 | J34: No | K34: 0.5 | L34: =I34*K34 -> 4675 | M34: =I34-L34 -> 4675 | N34: Booked in VIkas | O34: 46113 | P34: DCO2601876 | Z34: =G34 -> 93500 | AA34: =I34 -> 9350 | AB34: =M34 -> 4675
A35: 46099 | B35: Amit Gandhi | C35: Micro | D35: Nutricia Middle East DMCC | E35: Adobe License (LPO # 4505967699) | F35: Licenses | G35: 1938.36 | H35: =I35/G35 -> 0.10796756 | I35: 209.28 | J35: No | K35: 0.5 | L35: =I35*K35 -> 104.64 | M35: =I35-L35 -> 104.64 | N35: Booked in VIkas | O35: 46113 | P35: DCO2601784 | W35: =G35 -> 1938.36 | X35: =Y35+210 -> 419.28 | Y35: 209.28
I36: =H36*G36 -> 0 | L36: =I36*K36 -> 0 | M36: =I36-L36 -> 0
I37: =H37*G37 -> 0 | L37: =I37*K37 -> 0 | M37: =I37-L37 -> 0
I38: =H38*G38 -> 0 | L38: =I38*K38 -> 0 | M38: =I38-L38 -> 0
I39: =H39*G39 -> 0 | L39: =I39*K39 -> 0 | M39: =I39-L39 -> 0
I40: =H40*G40 -> 0 | L40: =I40*K40 -> 0 | M40: =I40-L40 -> 0
...

Sheet Opportunity Tracker
A1: Porposal Date | B1: Account Manager | C1: Presales | D1: Customer | E1: Project Description | F1: Division | G1: Project Type | H1: Proposal Value | I1: GP% | J1: GP Value | K1: NP Value | L1: Status
A2: 45972 | B2: Amit Gandhi | C2: Sriraj | D2: Department of Economy & Tourism | E2: Visitor Management System - Convexsol | F2: MSDT | G2: Other Application | H2: 85650 | I2: 0.3 | J2: =H2*I2 -> 25695 | K2: =J2*20% -> 5139 | L2: On Hold
A3: 46001 | B3: Amit Gandhi | C3: Rajendran / Kumar | D3: Amlak Finance PJSC | E3: Azure Blog Storage + Veeam Backup | F3: MSDT | G3: Cloud | H3: 49999.899 | I3: 0.22070514 | J3: =H3*I3 -> 11035.235 | K3: =J3*50% -> 5517.6174 | L3: Lost
A4: 46006 | B4: Amit Gandhi | C4: Aparna | D4: Dabur International Limited (DXB) | E4: Cisco Renewal | F4: NW | G4: Network | H4: 80236.166 | I4: 0.15 | J4: =H4*I4 -> 12035.425 | K4: =J4*50% -> 6017.7124 | L4: 0.5
A5: 46006 | B5: Amit Gandhi | C5: Aparna | D5: Naturelle LLC (RAK) | E5: Cisco Renewal | F5: NW | G5: Network | H5: 122638.34 | I5: 0.15 | J5: =H5*I5 -> 18395.751 | K5: =J5*50% -> 9197.8753 | L5: 0.5
A6: 46007 | B6: Amit Gandhi | C6: Rishabh | D6: Amlak Finance PJSC | E6: Email Security Gateway (Checkpoint) | F6: MSDT | G6: Cybersecurity | H6: 212516 | I6: 0.2 | J6: =H6*I6 -> 42503.2 | K6: =J6*50% -> 21251.6 | L6: On Hold
A7: 46023 | B7: Amit Gandhi | C7: Ali Siddiqui | D7: Naturelle LLC | E7: Cisco Wi-Fi Upgrade | F7: NW | G7: Network | H7: 261940.15 | I7: 0.2 | J7: =H7*I7 -> 52388.03 | K7: =J7*50% -> 26194.015 | L7: Lost
A8: 46023 | B8: Amit Gandhi | C8: Rajendran | D8: Amlak Finance PJSC | E8: AVD Assessment | F8: MSDT | G8: Cloud | H8: =(12000*0.95)*3.6725 -> 41866.5 | I8: 1 | J8: =H8*I8 -> 41866.5 | K8: =J8*50% -> 20933.25 | L8: 0.8
A9: 46023 | B9: Amit Gandhi | C9: Rajendran | D9: Arenco Real Estate Co LLC | E9: M365 Upgrade (7 Years) | F9: MSDT | G9: Cloud | H9: 8453895 | I9: 0.1 | J9: =H9*I9 -> 845389.5 | K9: =J9*50% -> 422694.75 | L9: 0.5
A10: 46036 | B10: Amit Gandhi | C10: Thejas | D10: Arenco Real Estate Co LLC | E10: Cisco Telephony Upgrade for Marketing Department | F10: NW | G10: Hardware | H10: 16084.154 | I10: 0.15 | J10: =H10*I10 -> 2412.6232 | K10: =J10*50% -> 1206.3116 | L10: Lost
A11: 46048 | B11: Amit Gandhi | D11: Naturelle LLC | E11: AutoCAD License | F11: Micro | G11: Licenses | H11: 2060.27 | I11: 0.1 | J11: =H11*I11 -> 206.027 | K11: =J11*50% -> 103.0135 | L11: On Hold
A12: 46055 | B12: Amit Gandhi | D12: Arenco Real Estate Co LLC | E12: Fortinet Refresh - HO VPN Firewall | F12: NW | G12: Hardware | H12: 96632.256 | I12: 0.06 | J12: =H12*I12 -> 5797.9354 | K12: =J12*50% -> 2898.9677 | L12: Lost
A13: 46055 | B13: Amit Gandhi | C13: Rishabh | D13: Al Farwaniya Property Developments Limited | E13: Managed Services - NOC, EUS & Systems | F13: MSDT | G13: Managed Services | H13: 220000 | I13: 1 | J13: =H13*I13 -> 220000 | K13: =J13*30% -> 66000 | L13: 0.8
A14: 46064 | B14: Amit Gandhi | D14: Arenco Real Estate Co LLC | E14: HP Switch SFP Modules | F14: NW | G14: Hardware | H14: 10000 | I14: 0.1 | J14: =H14*I14 -> 1000 | K14: =J14*30% -> 300 | L14: Lost
A15: 46072 | B15: Amit Gandhi | C15: Adnan / Thejas | D15: Dollar Rent A Car | E15: Team Integration with Telephony System and Call Center | F15: NW | G15: Telecom | H15: 450000 | I15: 0.23609164 | J15: =H15*I15 -> 106241.24 | K15: =J15*50% -> 53120.62 | L15: 0.5
A16: 46083 | B16: Amit Gandhi | D16: Thrifty Rent A Car | E16: Voxtron Contact Center Configuration | F16: NW | G16: Licenses | H16: 15400 | I16: 0.090909091 | J16: =H16*I16 -> 1400 | K16: =J16*50% -> 700 | L16: 0.8
A17: 46084 | B17: Amit Gandhi | D17: Department of Economy & Tourism | E17: RFP: Mood Tracker | F17: MSDT | G17: Other Application | H17: 50000 | I17: 0.2 | J17: =H17*I17 -> 10000 | K17: =J17*50% -> 5000 | L17: Didn’t Participate
A18: 46092 | B18: Amit Gandhi | D18: Al Farwaniya Property Developments Limited | E18: Guest Wifi Management Portal (Captive) | F18: NW | G18: Telecom | H18: 100000 | I18: 0.2 | J18: =H18*I18 -> 20000 | K18: =J18*50% -> 10000 | L18: Didn’t Participate
A19: 46090 | B19: Amit Gandhi | D19: Al Naboodah Construction Group LLC | E19: IT Infrastructure Migration & Separation | F19: MSDT | G19: Cloud | H19: 1260455.1 | I19: 0.25 | J19: =H19*I19 -> 315113.76 | K19: =J19*50% -> 157556.88 | L19: 0.5
A20: 46105 | B20: Amit Gandhi | C20: Rishabh | D20: Amlak Finance PJSC | E20: Microsoft Defender (MDO / EOP) for Office PS | F20: MSDT | G20: Cybersecurity | H20: 45000 | I20: 1 | J20: =H20*I20 -> 45000 | K20: =J20*50% -> 22500 | L20: 0.8
A21: 46105 | B21: Amit Gandhi | C21: Rishabh | D21: Amlak Finance PJSC | E21: DLP Services | F21: MSDT | G21: Cybersecurity | H21: 35000 | I21: 1 | J21: =H21*I21 -> 35000 | K21: =J21*50% -> 17500 | L21: 0.5
A22: 45741 | B22: Amit Gandhi | C22: Aparna | D22: Al Farwaniya Property Developments Limited | E22: Cisco Renewal | F22: NW | G22: Licenses | H22: 200000 | I22: 0.1 | J22: =H22*I22 -> 20000 | K22: =J22*50% -> 10000 | L22: 0.5
A23: 46110 | B23: Amit Gandhi | C23: Rishabh | D23: Emirates Transport | E23: IT Operations Managed Services | F23: MSDT | G23: Managed Services | H23: 8872000 | I23: 0.5 | J23: =H23*I23 -> 4436000 | K23: =J23*50% -> 2218000 | L23: 0.5
A24: 46112 | B24: Amit Gandhi | C24: Rajendran | D24: Amlak Finance PJSC | E24: Microsoft Defender for Office 365 licenses | F24: MSDT | G24: Licenses | H24: 27235 | I24: 0.05 | J24: =H24*I24 -> 1361.75 | K24: =J24*50% -> 680.875 | L24: 0.5
A25: 46112 | B25: Amit Gandhi | C25: Technocom | D25: Amlak Finance PJSC | E25: DR Movement | F25: ELV | G25: ELV | H25: 165000 | I25: 0.3 | J25: =H25*I25 -> 49500 | K25: =J25*50% -> 24750 | L25: 0.5
A26: 46114 | B26: Amit Gandhi | C26: Adnan | D26: Nutricia Middle East DMCC | E26: Cisco WAP - 5 Units | F26: NW | G26: Hardware | H26: 23497.016 | I26: 0.1 | J26: =H26*I26 -> 2349.7016 | K26: =J26*50% -> 1174.8508 | L26: 0.5
A27: 46120 | B27: Amit Gandhi | D27: Arenco Real Estate Co LLC | E27: Forti Token: 175 | F27: NW | G27: Licenses | H27: 48024.042 | I27: 0.12119565 | J27: =H27*I27 -> 5820.3051 | K27: =J27*50% -> 2910.1525 | L27: 0.8
A28: 46122 | B28: Amit Gandhi | D28: Arenco Real Estate Co LLC | E28: Forti Manager | F28: NW | G28: Licenses | H28: 16127.265 | I28: 0.15115538 | J28: =H28*I28 -> 2437.7229 | K28: =J28*50% -> 1218.8615 | L28: 0.8
A29: 46122 | B29: Amit Gandhi | D29: Arenco Real Estate Co LLC | E29: Wallix Addon Licenses + Upgrade | F29: MSDT | G29: Licenses | H29: =20816.64/0.8 -> 26020.8 | I29: 0.2 | J29: =H29*I29 -> 5204.16 | K29: =J29*50% -> 2602.08 | L29: 0.4
A30: 46122 | B30: Amit Gandhi | D30: Arenco Real Estate Co LLC | E30: Crowdstrike Addon Licenses | F30: MSDT | G30: Licenses | H30: 102104.69 | I30: 0.07 | J30: =H30*I30 -> 7147.3281 | K30: =J30*50% -> 3573.664 | L30: 0.5
A31: 46129 | B31: Amit Gandhi | D31: Arenco Real Estate Co LLC | E31: Mimecast Renewal | F31: MSDT | G31: Licenses | J31: =H31*I31 -> 0 | L31: 0.4
A32: 46132 | B32: Amit Gandhi | D32: Arenco Real Estate Co LLC | E32: IBM Instana | F32: MSDT | G32: Licenses | J32: =H32*I32 -> 0 | L32: 0.4

Sheet ET
A1: Emirates Transport
A2: DCO Number | B2: DCO Date | C2: Customer Name | D2: LPO Number | E2: LPO Value | F2: Status | G2: Finance Approval | H2: Location / Details
A3: Booked under Tawfeeq
A4: DCO2409838 | B4: 45656 | C4: EMIRATES PUBLIC TRANSPORT AND SERVICES COMPANY | D4: 2422401348 | E4: 15435 | F4: Pending | G4: APPROVED | H4: IDF2 Shifting _ AlQusais
A5: DCO2500395 | B5: 45673 | C5: EMIRATES PUBLIC TRANSPORT AND SERVICES COMPANY | D5: 2522400037 | E5: 10080 | F5: Partial | G5: APPROVED | H5: RAK Br. Workstations, Security Main Gate RAK, HO & FUJ Br. Guard Rm
A7: Transfer from Tawfeeq to Amit
A8: DCO2503867 | B8: 45797 | C8: EMIRATES PUBLIC TRANSPORT AND SERVICES COMPANY | D8: 2522400480 | E8: 253995 | F8: Partial | G8: APPROVED | H8: Al Warsan
A9: DCO2507319 / DCO2601211 | B9: 45918 | C9: EMIRATES PUBLIC TRANSPORT AND SERVICES COMPANY | D9: 2522400931 | E9: 21396.97 | F9: Pending | G9: APPROVED | H9: HQ Block D Control Room
B10: 45960 | C10: EMIRATES PUBLIC TRANSPORT AND SERVICES COMPANY | D10: 2522401112 | E10: 29620.24 | H10: Al Asma Capital City
A12: Booked under Mitesh
B13: 45917 | C13: EMIRATES PUBLIC TRANSPORT AND SERVICES COMPANY | D13: 2522400958 | E13: 15447.61 | H13: Madinat Zayed Station
B14: 45917 | C14: EMIRATES PUBLIC TRANSPORT AND SERVICES COMPANY | D14: 2522400959 | E14: 11254.52 | H14: RAK Al Dhait Stn. Admin Block
B15: 45917 | C15: EMIRATES PUBLIC TRANSPORT AND SERVICES COMPANY | D15: 2522400957 | E15: 9441.92 | H15: Baniyas Station AUH
A16: DCO2507318 | B16: 45918 | C16: EMIRATES PUBLIC TRANSPORT AND SERVICES COMPANY | D16: 2522400951 | E16: 17794.31 | F16: Pending | G16: APPROVED | H16: Structured Cabling System @ Masfoot Station, as per the
H17: BPA 2522400879 with Alpha Data LLC.
A20: LPO Not processed
B21: 45960 | C21: EMIRATES PUBLIC TRANSPORT AND SERVICES COMPANY | D21: 2522401106 | E21: 132500 | H21: HQ Data Center Passive Uplifting & Modernization
C24: 45778
C25: 46874

Sheet Morohub
A1: Line Item | B1: Customer Name | C1: LPO Number | D1: Description | E1: DCO Date | F1: DCO Number | G1: Exc VAT | I1: Invoiced Till Date | J1: Balance to be invoiced | K1: Tawfeeq | L1: Amit
A2: 2 | B2: DATA HUB INTEGRATED SOLUTIONS MORO L.L.C. | C2: 3224250221 | D2: Attendance Control Automation Errors In, In Out, Out | E2: 45740 | F2: DCO2502310 | G2: =255000 -> 255000 | H2: =G2*1.05 -> 267750 | I2: =SUM(K2:O2) -> 178500 | J2: =G2-I2 -> 76500 | K2: =48000+54000 -> 102000 | L2: =40500+36000 -> 76500
A3: 4 | B3: DATA HUB INTEGRATED SOLUTIONS MORO L.L.C. | C3: 3224250888 | D3: Cyber 360 CR | E3: 46034 | F3: DCO2600249 | G3: 110000 | H3: =G3*1.05 -> 115500 | I3: =SUM(K3:O3) -> 0 | J3: =G3-I3 -> 110000
G5: =SUM(G2:G4) -> 365000 | I5: =SUM(I2:I4) -> 178500 | J5: =SUM(J2:J4) -> 186500 | K5: =SUM(K2:K4) -> 102000 | L5: =SUM(L2:L4) -> 76500
C7: LPO Value | D7: Billing Value | E7: Billing Date | N7: =N14*0.85 -> 44200 | O7: =O14*0.85 -> 22100
B8: DATA HUB INTEGRATED SOLUTIONS MORO L.L.C. LPO # 3224000833 Description: Development of Cyber360 Portal for DEWA DCO # DCO2409084 | C8: 260000 | K8: =K14*0.85 -> 22100 | L8: =L14*0.85 -> 66300 | M8: =M14*0.85 -> 66300 | N8: =N14*0.85 -> 44200 | O8: =O14*0.85 -> 22100
D9: 26000 | E9: 45639 | K9: 2025001003 | L9: 2025002005 | M9: 2025002005
D10: 78000 | E10: 45692
D11: 78000 | E11: 45776
D12: 52000 | E12: 45911 | K12: Tawfeeq | N12: Amit
A13: 3 | B13: DATA HUB INTEGRATED SOLUTIONS MORO L.L.C. | C13: 3224251128 | D13: Case Management Portal Development project | E13: 46031 | F13: DCO2600185 | G13: 610000 | H13: =G13*1.05 -> 640500 | I13: =SUM(K13:O13) -> 0 | J13: =G13-I13 -> 610000 | P13: Transfer to Natarajan
A14: 1 | B14: DATA HUB INTEGRATED SOLUTIONS MORO L.L.C. | C14: 3224000833 | D14: Development of Cyber360 Portal for DEWA | E14: 45624 | F14: DCO2409084 | G14: 260000 | H14: =G14*1.05 -> 273000 | I14: =SUM(K14:O14) -> 260000 | J14: =G14-I14 -> 0 | K14: 26000 | L14: 78000 | M14: 78000 | N14: 52000 | O14: 26000 | Q14: =SUM(K14:M14)*0.85 -> 154700

Sheet Reem Mall
A1: Name | B1: Designation | C1: Mobile Number | D1: Email ID | E1: Remarks
A2: Amit Gandhi | B2: Manager - Managed Services Sales | C2: 971 557180121 | D2: amitkumar@alphadxb.com | E2: POC for Requirements, contracts, LPO & Relationship Management
A3: Natarajan Gnanasekar | B3: Director- Digital Transformation | C3: 971 508552324 | D3: natarajan@alphadxb.com | E3: POC for Division level support
A4: Parvez A. Ahamed | B4: Director of Services | C4: 971 504951062 | D4: parvez@alphadxb.com | E4: POC for management level Escalation
A5: Tarig Ammar | B5: Operations Lead | C5: 971 564645362 | D5: tarig@alphadxb.com | E5: POC for Day-to-Day operations related support
A6: Obaidha Mydeen | B6: NOC Service Coordinator | C6: 971 43079799 | D6: Obaidha@alphadxb.com | E6: POC for NOC coordinator
A7: Rammohan Soundararajan | B7: Sr. Manager - Managed Services Ops | C7: 971 501005355 | D7: Rammohan@alphadxb.com | E7: POC for Service Delivery improvement
A8: Jeswin Joseph | B8: Network Engineer | C8: 971 508020978 | D8: jeswin@alphadxb.com | E8: POC for Network Support
A9: Mohammad Shahzada Khan | B9: Senior Network Engineer | C9: 971 543877689 | D9: Shahzada@alphadxb.com | E9: POC for Network Support
A10: Faizan Akhtar | B10: Customer Support Engineer | C10: 971 564585673 | D10: faizan@alphadxb.com | E10: POC for L1 Support
A11: Faraz Ahmed | B11: System Administrator | C11: 971 562096055 | D11: faraz@alphadxb.com | E11: POC for Systems Support

Sheet Arenco
A1: LPO # 25000112 | B1: Veeam VCSP O365 Renewal
A2: Start Date | B2: End Date | C2: Invoice Value | D2: Split 1 | E2: Split 2
A3: 45870 | B3: 45900 | C3: 51840 | D3: 6220.8 | E3: 45619.2
A4: 45901 | B4: 45930
A5: 45931 | B5: 45961
A6: 45962 | B6: 45991
A7: 45992 | B7: 46022
A8: 46023 | B8: 46053
A9: 46054 | B9: 46081 | C9: 8640
A10: 46082 | B10: 46112 | C10: 8640
A11: 46113 | B11: 46142 | C11: 8640
A12: 46143 | B12: 46173 | C12: 8640
A13: 46174 | B13: 46203 | C13: 8640
A14: 46204 | B14: 46234 | C14: 8640
C16: =SUM(C3:C15) -> 103680
F19: 4166.67 | G19: =F19*12 -> 50000.04 | H19: =G19/4 -> 12500.01
F20: 2000 | G20: =F20*12 -> 24000
