Workbook

Sheet Summary
B2: Account Manager :-- | C2: Mitesh Sheth
E4: 4 | F4: [--- need to cange the respective month (Jan- 1, Feb- 2, Mar -3)
B5: Top Line Target 2026 | C5: 3684211 | D5: GP Target 2026 | E5: 1961000 | F5: NP Target 2026 | G5: 980500 | H5: {-- enter your targets
B6: YTD Target | C6: =C5/12*E4 -> 1228070.3 | D6: YTD Target | E6: =E5/12*E4 -> 653666.67 | F6: YTD Target | G6: =G5/12*E4 -> 326833.33
B7: Acheived Till Date (previous month) | C7: =H14 -> 230524.87 | D7: Acheived Till Date (previous month) | E7: =(L14+L15+L16) -> 437465.17 | F7: Acheived Till Date (previous month) | G7: =(Q14+Q15+Q16) -> 262310.21
B8: Current Month Forecast | C8: =H15 -> 421877.63 | D8: Current Month Forecast | E8: =L16 -> 121319.92 | F8: Current Month Forecast | G8: =Q16 -> 52748
B9: Delta | C9: =(C8+C7)-C6 -> -575667.83 | D9: Delta | E9: =(E8+E7)-E6 -> -94881.577 | F9: Delta | G9: =(G8+G7)-G6 -> -11775.124
B10: Delta in % | C10: =C9/C6 -> -0.46875803 | D10: Delta in % | E10: =E9/E6 -> -0.14515285 | F10: Delta in % | G10: =G9/G6 -> -0.036027916
B12: Booking details | F12: Billing details
C13: Top Line | D13: GP Value | E13: NP Value | G13: Top Line Target | H13: Top Line Billing | I13: Top Line YTD Delta | J13: Top Line YTD Variance | K13: GP Target | L13: GP Billing | M13: GP YTD Delta | N13: YTD Variance % | P13: NP Target | Q13: NP Billing | R13: NP YTD Delta | S13: YTD Variance %
B14: 46023 | C14: =SUMIF('Booking & Billing Forecast'!O:O,Summary!B:B,'Booking & Billing Forecast'!G:G) -> 6950 | D14: =SUMIF('Booking & Billing Forecast'!O:O,Summary!B:B,'Booking & Billing Forecast'!I:I) -> 6950 | E14: =SUMIF('Booking & Billing Forecast'!O:O,Summary!B:B,'Booking & Billing Forecast'!M:M) -> 2085 | F14: 46023 | G14: =C5/12*1 -> 307017.58 | H14: =SUM('Booking & Billing Forecast'!Q:Q) -> 230524.87 | I14: =H14-G14 -> -76492.713 | J14: =I14/G14 -> -0.24914766 | K14: =E5/12*1 -> 163416.67 | L14: =SUM('Booking & Billing Forecast'!R:R) -> 122528.09 | M14: =L14-K14 -> -40888.577 | N14: =M14/K14 -> -0.25021057 | P14: =G5/12*1 -> 81708.333 | Q14: =SUM('Booking & Billing Forecast'!S:S) -> 86618.21 | R14: =Q14-P14 -> 4909.8767 | S14: =R14/P14 -> 0.06009028
B15: 46054 | C15: =SUMIF('Booking & Billing Forecast'!O:O,Summary!B:B,'Booking & Billing Forecast'!G:G) -> 311787.41 | D15: =SUMIF('Booking & Billing Forecast'!O:O,Summary!B:B,'Booking & Billing Forecast'!I:I) -> 129011.42 | E15: =SUMIF('Booking & Billing Forecast'!O:O,Summary!B:B,'Booking & Billing Forecast'!M:M) -> 64505.71 | F15: 46054 | G15: =C5/12*2 -> 614035.17 | H15: =SUM('Booking & Billing Forecast'!T:T) -> 421877.63 | I15: =SUM(H14:H15)-G15 -> 38367.333 | J15: =I15/G15 -> 0.062483935 | K15: =E5/12*2 -> 326833.33 | L15: =SUM('Booking & Billing Forecast'!U:U) -> 193617.16 | M15: =SUM(L14:L15)-K15 -> -10688.084 | N15: =M15/K15 -> -0.032701939 | P15: =G5/12*2 -> 163416.67 | Q15: =SUM('Booking & Billing Forecast'!V:V) -> 122944 | R15: =SUM(Q14:Q15)-P15 -> 46145.543 | S15: =R15/P15 -> 0.28237966 | U15: 122944 | V15: =U15-Q15 -> 0.00049999999
B16: 46082 | C16: =SUMIF('Booking & Billing Forecast'!O:O,Summary!B:B,'Booking & Billing Forecast'!G:G) -> 367200 | D16: =SUMIF('Booking & Billing Forecast'!O:O,Summary!B:B,'Booking & Billing Forecast'!I:I) -> 367200 | E16: =SUMIF('Booking & Billing Forecast'!O:O,Summary!B:B,'Booking & Billing Forecast'!M:M) -> 108000 | F16: 46082 | G16: =C5/12*3 -> 921052.75 | H16: =SUM('Booking & Billing Forecast'!W:W) -> 249728.34 | I16: =SUM(H14:H16)-G16 -> -18921.91 | J16: =I16/G16 -> -0.020543785 | K16: =E5/12*3 -> 490250 | L16: =SUM('Booking & Billing Forecast'!X:X) -> 121319.92 | M16: =SUM(L14:L16)-K16 -> -52784.83 | N16: =M16/K16 -> -0.10766921 | P16: =G5/12*3 -> 245125 | Q16: =SUM('Booking & Billing Forecast'!Y:Y) -> 52748 | R16: =SUM(Q14:Q16)-P16 -> 17185.209 | S16: =R16/P16 -> 0.070107943 | T16: Q1 | U16: 38341 | V16: =U16-Q16 -> -14407
B17: 46113 | C17: =SUMIF('Booking & Billing Forecast'!O:O,Summary!B:B,'Booking & Billing Forecast'!G:G) -> 312058 | D17: =SUMIF('Booking & Billing Forecast'!O:O,Summary!B:B,'Booking & Billing Forecast'!I:I) -> 204819.84 | E17: =SUMIF('Booking & Billing Forecast'!O:O,Summary!B:B,'Booking & Billing Forecast'!M:M) -> 37389.918 | F17: 46113 | G17: =C5/12*4 -> 1228070.3 | H17: =SUM('Booking & Billing Forecast'!Z:Z) -> 225649.32 | I17: =SUM(H14:H17)-G17 -> -100290.17 | J17: =I17/G17 -> -0.081664845 | K17: =E5/12*4 -> 653666.67 | L17: =SUM('Booking & Billing Forecast'!AA:AA) -> 187137.06 | M17: =SUM(L14:L17)-K17 -> -29064.437 | N17: =M17/K17 -> -0.044463698 | P17: =G5/12*4 -> 326833.33 | Q17: =SUM('Booking & Billing Forecast'!AB:AB) -> 86904.21 | R17: =SUM(Q14:Q17)-P17 -> 22381.086 | S17: =R17/P17 -> 0.068478591
B18: 46143 | C18: =SUMIF('Booking & Billing Forecast'!O:O,Summary!B:B,'Booking & Billing Forecast'!G:G) -> 284500 | D18: =SUMIF('Booking & Billing Forecast'!O:O,Summary!B:B,'Booking & Billing Forecast'!I:I) -> 249536.8 | E18: =SUMIF('Booking & Billing Forecast'!O:O,Summary!B:B,'Booking & Billing Forecast'!M:M) -> 80368.4 | F18: 46143 | G18: =C5/12*5 -> 1535087.9 | H18: =SUM('Booking & Billing Forecast'!AC:AC) -> 438399.52 | I18: =SUM(H14:H18)-G18 -> 31091.763 | J18: =I18/G18 -> 0.02025406 | K18: =E5/12*5 -> 817083.33 | L18: =SUM('Booking & Billing Forecast'!AD:AD) -> 280314.63 | M18: =SUM(L14:L18)-K18 -> 87833.526 | N18: =M18/K18 -> 0.10749641 | P18: =G5/12*5 -> 408541.67 | Q18: =SUM('Booking & Billing Forecast'!AE:AE) -> 103099.26 | R18: =SUM(Q14:Q18)-P18 -> 43772.018 | S18: =R18/P18 -> 0.10714211
B19: 46174 | C19: =SUMIF('Booking & Billing Forecast'!O:O,Summary!B:B,'Booking & Billing Forecast'!G:G) -> 0 | D19: =SUMIF('Booking & Billing Forecast'!O:O,Summary!B:B,'Booking & Billing Forecast'!I:I) -> 0 | E19: =SUMIF('Booking & Billing Forecast'!O:O,Summary!B:B,'Booking & Billing Forecast'!M:M) -> 0 | F19: 46174 | G19: =C5/12*6 -> 1842105.5 | H19: =SUM('Booking & Billing Forecast'!AF:AF) -> 202448.66 | I19: =SUM(H14:H19)-G19 -> -73477.16 | J19: =I19/G19 -> -0.039887596 | K19: =E5/12*6 -> 980500 | L19: =SUM('Booking & Billing Forecast'!AG:AG) -> 71708.06 | M19: =SUM(L14:L19)-K19 -> -3875.0805 | N19: =M19/K19 -> -0.0039521474 | P19: =G5/12*6 -> 490250 | Q19: =SUM('Booking & Billing Forecast'!AH:AH) -> 35860.94 | R19: =SUM(Q14:Q19)-P19 -> -2075.3755 | S19: =R19/P19 -> -0.0042333004 | T19: Q2
B20: 46204 | C20: =SUMIF('Booking & Billing Forecast'!O:O,Summary!B:B,'Booking & Billing Forecast'!G:G) -> 0 | D20: =SUMIF('Booking & Billing Forecast'!O:O,Summary!B:B,'Booking & Billing Forecast'!I:I) -> 0 | E20: =SUMIF('Booking & Billing Forecast'!O:O,Summary!B:B,'Booking & Billing Forecast'!M:M) -> 0 | F20: 46204 | G20: =C5/12*7 -> 2149123.1 | H20: =SUM('Booking & Billing Forecast'!AI:AI) -> 85542.66 | I20: =SUM(H14:H20)-G20 -> -294952.08 | J20: =I20/G20 -> -0.13724299 | K20: =E5/12*7 -> 1143916.7 | L20: =SUM('Booking & Billing Forecast'!AJ:AJ) -> 71349.06 | M20: =SUM(L14:L20)-K20 -> -95942.687 | N20: =M20/K20 -> -0.083872095 | P20: =G5/12*7 -> 571958.33 | Q20: =SUM('Booking & Billing Forecast'!AK:AK) -> 22597.54 | R20: =SUM(Q14:Q20)-P20 -> -61186.169 | S20: =R20/P20 -> -0.10697662 | W20: =52748-Q16 -> 0
B21: 46235 | C21: =SUMIF('Booking & Billing Forecast'!O:O,Summary!B:B,'Booking & Billing Forecast'!G:G) -> 0 | D21: =SUMIF('Booking & Billing Forecast'!O:O,Summary!B:B,'Booking & Billing Forecast'!I:I) -> 0 | E21: =SUMIF('Booking & Billing Forecast'!O:O,Summary!B:B,'Booking & Billing Forecast'!M:M) -> 0 | F21: 46235 | G21: =C5/12*8 -> 2456140.7 | H21: =SUM('Booking & Billing Forecast'!AL:AL) -> 85542.66 | I21: =SUM(H14:H21)-G21 -> -516427.01 | J21: =I21/G21 -> -0.21025954 | K21: =E5/12*8 -> 1307333.3 | L21: =SUM('Booking & Billing Forecast'!AM:AM) -> 71349.06 | M21: =SUM(L14:L21)-K21 -> -188010.29 | N21: =M21/K21 -> -0.14381206 | P21: =G5/12*8 -> 653666.67 | Q21: =SUM('Booking & Billing Forecast'!AN:AN) -> 22597.54 | R21: =SUM(Q14:Q21)-P21 -> -120296.96 | S21: =R21/P21 -> -0.18403411
B22: 46266 | C22: =SUMIF('Booking & Billing Forecast'!O:O,Summary!B:B,'Booking & Billing Forecast'!G:G) -> 0 | D22: =SUMIF('Booking & Billing Forecast'!O:O,Summary!B:B,'Booking & Billing Forecast'!I:I) -> 0 | E22: =SUMIF('Booking & Billing Forecast'!O:O,Summary!B:B,'Booking & Billing Forecast'!M:M) -> 0 | F22: 46266 | G22: =C5/12*9 -> 2763158.2 | H22: =SUM('Booking & Billing Forecast'!AO:AO) -> 43346.66 | I22: =SUM(H14:H22)-G22 -> -780097.93 | J22: =I22/G22 -> -0.28232112 | K22: =E5/12*9 -> 1470750 | L22: =SUM('Booking & Billing Forecast'!AP:AP) -> 40433.06 | M22: =SUM(L14:L22)-K22 -> -310993.9 | N22: =M22/K22 -> -0.21145259 | P22: =G5/12*9 -> 735375 | Q22: =SUM('Booking & Billing Forecast'!AQ:AQ) -> 18716.54 | R22: =SUM(Q14:Q22)-P22 -> -183288.76 | S22: =R22/P22 -> -0.24924529 | T22: Q3
B23: 46296 | C23: =SUMIF('Booking & Billing Forecast'!O:O,Summary!B:B,'Booking & Billing Forecast'!G:G) -> 0 | D23: =SUMIF('Booking & Billing Forecast'!O:O,Summary!B:B,'Booking & Billing Forecast'!I:I) -> 0 | E23: =SUMIF('Booking & Billing Forecast'!O:O,Summary!B:B,'Booking & Billing Forecast'!M:M) -> 0 | F23: 46296 | G23: =C5/12*10 -> 3070175.8 | H23: =SUM('Booking & Billing Forecast'!AR:AR) -> 19816.66 | I23: =SUM(H14:H23)-G23 -> -1067298.9 | J23: =I23/G23 -> -0.34763444 | K23: =E5/12*10 -> 1634166.7 | L23: =SUM('Booking & Billing Forecast'!AS:AS) -> 16903.06 | M23: =SUM(L14:L23)-K23 -> -457507.51 | N23: =M23/K23 -> -0.2799638 | P23: =G5/12*10 -> 817083.33 | Q23: =SUM('Booking & Billing Forecast'!AT:AT) -> 8626.54 | R23: =SUM(Q14:Q23)-P23 -> -256370.55 | S23: =R23/P23 -> -0.31376304
B24: 46327 | C24: =SUMIF('Booking & Billing Forecast'!O:O,Summary!B:B,'Booking & Billing Forecast'!G:G) -> 0 | D24: =SUMIF('Booking & Billing Forecast'!O:O,Summary!B:B,'Booking & Billing Forecast'!I:I) -> 0 | E24: =SUMIF('Booking & Billing Forecast'!O:O,Summary!B:B,'Booking & Billing Forecast'!M:M) -> 0 | F24: 46327 | G24: =C5/12*11 -> 3377193.4 | H24: =SUM('Booking & Billing Forecast'!AU:AU) -> 19816.66 | I24: =SUM(H14:H24)-G24 -> -1354499.8 | J24: =I24/G24 -> -0.40107261 | K24: =E5/12*11 -> 1797583.3 | L24: =SUM('Booking & Billing Forecast'!AV:AV) -> 16903.06 | M24: =SUM(L14:L24)-K24 -> -604021.11 | N24: =M24/K24 -> -0.33601842 | P24: =G5/12*11 -> 898791.67 | Q24: =SUM('Booking & Billing Forecast'!AW:AW) -> 8626.54 | R24: =SUM(Q14:Q24)-P24 -> -329452.34 | S24: =R24/P24 -> -0.36655029
B25: 46357 | C25: =SUMIF('Booking & Billing Forecast'!O:O,Summary!B:B,'Booking & Billing Forecast'!G:G) -> 0 | D25: =SUMIF('Booking & Billing Forecast'!O:O,Summary!B:B,'Booking & Billing Forecast'!I:I) -> 0 | E25: =SUMIF('Booking & Billing Forecast'!O:O,Summary!B:B,'Booking & Billing Forecast'!M:M) -> 0 | F25: 46357 | G25: =C5/12*12 -> 3684211 | H25: =SUM('Booking & Billing Forecast'!AX:AX) -> 10650 | I25: =SUM(H14:H25)-G25 -> -1650867.4 | J25: =I25/G25 -> -0.44809251 | K25: =E5/12*12 -> 1961000 | L25: =SUM('Booking & Billing Forecast'!AY:AY) -> 7736.4 | M25: =SUM(L14:L25)-K25 -> -759701.38 | N25: =M25/K25 -> -0.38740509 | P25: =G5/12*12 -> 980500 | Q25: =SUM('Booking & Billing Forecast'!AZ:AZ) -> 5443.2 | R25: =SUM(Q14:Q25)-P25 -> -405717.48 | S25: =R25/P25 -> -0.41378631 | T25: Q4
C26: =SUM(C14:C25) -> 1282495.4 | D26: =SUM(D14:D25) -> 957518.06 | E26: =SUM(E14:E25) -> 292349.03 | H26: =SUM(H14:H25) -> 2033343.6 | L26: =SUM(L14:L25) -> 1201298.6 | Q26: =SUM(Q14:Q25) -> 574782.52
B29: Opportunity Summary
B30: Opportunity Pipelines | C30: Top Line | D30: GP Value | E30: NP Value
B31: 0.8 | C31: =SUMIF('Opportunity Tracker'!L:L,Summary!B:B,'Opportunity Tracker'!H:H) -> 1498215 | D31: =SUMIF('Opportunity Tracker'!L:L,Summary!B:B,'Opportunity Tracker'!J:J) -> 236766.17 | E31: =SUMIF('Opportunity Tracker'!L:L,Summary!B:B,'Opportunity Tracker'!K:K) -> 118383.09 | F31: Note to Pavi consider 100% book & Bill before Dec 2026
B32: 0.5 | C32: =SUMIF('Opportunity Tracker'!L:L,Summary!B:B,'Opportunity Tracker'!H:H) -> 4379616.9 | D32: =SUMIF('Opportunity Tracker'!L:L,Summary!B:B,'Opportunity Tracker'!J:J) -> 1637806.1 | E32: =SUMIF('Opportunity Tracker'!L:L,Summary!B:B,'Opportunity Tracker'!K:K) -> 846553.97 | F32: Note to Pavi - Don’t factor
B33: 0.4 | C33: =SUMIF('Opportunity Tracker'!L:L,Summary!B:B,'Opportunity Tracker'!H:H) -> 0 | D33: =SUMIF('Opportunity Tracker'!L:L,Summary!B:B,'Opportunity Tracker'!J:J) -> 0 | E33: =SUMIF('Opportunity Tracker'!L:L,Summary!B:B,'Opportunity Tracker'!K:K) -> 0
B34: Lost | C34: =SUMIF('Opportunity Tracker'!L:L,Summary!B:B,'Opportunity Tracker'!H:H) -> 0 | D34: =SUMIF('Opportunity Tracker'!L:L,Summary!B:B,'Opportunity Tracker'!J:J) -> 0 | E34: =SUMIF('Opportunity Tracker'!L:L,Summary!B:B,'Opportunity Tracker'!K:K) -> 0
B35: Hold | C35: =SUMIF('Opportunity Tracker'!L:L,Summary!B:B,'Opportunity Tracker'!H:H) -> 0 | D35: =SUMIF('Opportunity Tracker'!L:L,Summary!B:B,'Opportunity Tracker'!J:J) -> 0 | E35: =SUMIF('Opportunity Tracker'!L:L,Summary!B:B,'Opportunity Tracker'!K:K) -> 0
B36: Didn’t Participate | C36: =SUMIF('Opportunity Tracker'!L:L,Summary!B:B,'Opportunity Tracker'!H:H) -> 0 | D36: =SUMIF('Opportunity Tracker'!L:L,Summary!B:B,'Opportunity Tracker'!J:J) -> 0 | E36: =SUMIF('Opportunity Tracker'!L:L,Summary!B:B,'Opportunity Tracker'!K:K) -> 0
B37: Won Yet to be Booked in Vikas | C37: =SUMIF('Opportunity Tracker'!L:L,Summary!B:B,'Opportunity Tracker'!H:H) -> 0 | D37: =SUMIF('Opportunity Tracker'!L:L,Summary!B:B,'Opportunity Tracker'!J:J) -> 0 | E37: =SUMIF('Opportunity Tracker'!L:L,Summary!B:B,'Opportunity Tracker'!K:K) -> 0

Sheet Booking & Billing Forecast
A1: Date | B1: Account Manager | C1: Billing Division | D1: Customer | E1: Project Description | F1: Project Type | G1: Order Value | H1: GP% | I1: GP Value | J1: Internal Team involved | K1: Payroll % | L1: Payroll Cost | M1: NP Value | N1: Status | O1: Booking Month | P1: Vikas Invoice | Q1: Jan-26 | T1: Feb-26 | W1: Mar-26 | Z1: Apr-26 | AC1: May-26 | AF1: Jun-26 | AI1: Jul-26 | AL1: Aug-26 | AO1: Sept-26 | AR1: Oct-26 | AU1: Nov-26 | AX1: Dec-26
Q2: Invoice Value | R2: GP | S2: NP Value | T2: Invoice Value | U2: GP | V2: NP Value | W2: Invoice Value | X2: GP | Y2: NP Value | Z2: Invoice Value | AA2: GP | AB2: NP Value | AC2: Invoice Value | AD2: GP | AE2: NP Value | AF2: Invoice Value | AG2: GP | AH2: NP Value | AI2: Invoice Value | AJ2: GP | AK2: NP Value | AL2: Invoice Value | AM2: GP | AN2: NP Value | AO2: Invoice Value | AP2: GP | AQ2: NP Value | AR2: Invoice Value | AS2: GP | AT2: NP Value | AU2: Invoice Value | AV2: GP | AW2: NP Value | AX2: Invoice Value | AY2: GP | AZ2: NP Value
A3: 45808 | B3: Mitesh | C3: MSDT | D3: Kotak Mahindra (UK) Ltd. | E3: Managed Services - Incident Pack | F3: Managed Services | G3: 17000 | H3: 1 | I3: =H3*G3 -> 17000 | J3: Yes | K3: 0.7 | L3: =I3*K3 -> 11900 | M3: =I3-L3 -> 5100 | P3: DMT2500147 | Q3: 1416.66 | R3: 1416 | S3: 425 | T3: 1304 | U3: 1304 | V3: 391 | W3: 1444 | X3: 1444 | Y3: 433 | Z3: 1416.66 | AA3: 1416 | AB3: 425 | AC3: 1416.66 | AD3: 1416 | AE3: 425
A4: 45778 | B4: Mitesh | C4: MSDT | D4: Green Supplier Food Trading L.L.C | E4: Managed Services - NOC support | F4: Managed Services | G4: 144000 | H4: 1 | I4: =H4*G4 -> 144000 | J4: Yes | K4: 0.7 | L4: 57600 | M4: =I4-L4 -> 86400 | N4: Booked in VIkas | O4: 2025 | P4: DMT2500162 | T4: 32400 | U4: 32400 | V4: 19440 | W4: 3600 | X4: 1440 | Y4: 2160 | Z4: 12000 | AA4: 12000 | AB4: 7200 | AC4: 12000 | AD4: 12000 | AE4: 7200
A5: 45940 | B5: Mitesh | C5: MSDT | D5: Sustainable Food Supplies | E5: Extended devices - Managed Services (NOC) | F5: Managed Services | G5: 42000 | H5: 1 | I5: =H5*G5 -> 42000 | J5: Yes | K5: 0.7 | L5: =I5*K5 -> 29400 | M5: 12600 | P5: DMT2500263 | T5: 12034 | U5: 12034 | V5: 5158 | W5: 3657 | X5: 3657 | Y5: 1567 | Z5: 3500 | AA5: 3500 | AB5: 1050 | AC5: 3500 | AD5: 3500 | AE5: 1050 | AF5: 3500 | AG5: 3500 | AH5: 1050 | AI5: 3500 | AJ5: 3500 | AK5: 1050 | AL5: 3500 | AM5: 3500 | AN5: 1050 | AO5: 3500 | AP5: 3500 | AQ5: 1050 | AR5: 3500 | AS5: 3500 | AT5: 1050 | AU5: 3500 | AV5: 3500 | AW5: 1050
A6: 45940 | B6: Mitesh | C6: MSDT | D6: Sustainable Food Supplies | E6: Extended devices - ELV | F6: Managed Services | G6: 13000 | H6: 1 | I6: =H6*G6 -> 13000 | J6: Yes | K6: 0.7 | L6: =I6*K6 -> 9100 | M6: 6500 | P6: DMT2500265 | T6: 3761 | U6: 3761 | V6: 1880 | W6: 1132 | X6: 1132 | Y6: 566 | Z6: 1083.33 | AA6: 1083.33 | AB6: 541.67 | AC6: 1083.33 | AD6: 1083.33 | AE6: 541.67 | AF6: 1083.33 | AG6: 1083.33 | AH6: 541.67 | AI6: 1083.33 | AJ6: 1083.33 | AK6: 541.67 | AL6: 1083.33 | AM6: 1083.33 | AN6: 541.67 | AO6: 1083.33 | AP6: 1083.33 | AQ6: 541.67 | AR6: 1083.33 | AS6: 1083.33 | AT6: 541.67 | AU6: 1083.33 | AV6: 1083.33 | AW6: 541.67
A7: 45940 | B7: Mitesh | C7: MSDT | D7: Akhdar Trading | E7: Extended devices - Managed Services (NOC) | F7: Managed Services | G7: 42000 | H7: 1 | I7: =H7*G7 -> 42000 | J7: Yes | K7: 0.7 | L7: =I7*K7 -> 29400 | M7: 12600 | P7: DMT2500262 | T7: 12034 | U7: 12034 | V7: 5158 | W7: 3657 | X7: 3657 | Y7: 1567 | Z7: 3500 | AA7: 3500 | AB7: 1050 | AC7: 3500 | AD7: 3500 | AE7: 1050 | AF7: 3500 | AG7: 3500 | AH7: 1050 | AI7: 3500 | AJ7: 3500 | AK7: 1050 | AL7: 3500 | AM7: 3500 | AN7: 1050 | AO7: 3500 | AP7: 3500 | AQ7: 1050 | AR7: 3500 | AS7: 3500 | AT7: 1050 | AU7: 3500 | AV7: 3500 | AW7: 1050
A8: 45940 | B8: Mitesh | C8: MSDT | D8: Akhdar Trading | E8: Extended devices - ELV | F8: Managed Services | G8: 13000 | H8: 1 | I8: =H8*G8 -> 13000 | J8: Yes | K8: 0.7 | L8: =I8*K8 -> 9100 | M8: 6500 | P8: DMT2500267 | T8: 3761 | U8: 3761 | V8: 1880 | W8: 1132 | X8: 1132 | Y8: 566 | Z8: 1083.33 | AA8: 1083.33 | AB8: 541.67 | AC8: 1083.33 | AD8: 1083.33 | AE8: 541.67 | AF8: 1083.33 | AG8: 1083.33 | AH8: 541.67 | AI8: 1083.33 | AJ8: 1083.33 | AK8: 541.67 | AL8: 1083.33 | AM8: 1083.33 | AN8: 541.67 | AO8: 1083.33 | AP8: 1083.33 | AQ8: 541.67 | AR8: 1083.33 | AS8: 1083.33 | AT8: 541.67 | AU8: 1083.33 | AV8: 1083.33 | AW8: 541.67
A9: 45636 | B9: Mitesh | C9: MSDT | D9: Juma Al Majid Holding | E9: AWS Hosting | F9: Cloud | G9: 55200 | H9: 0.08 | I9: =H9*G9 -> 4416 | J9: Yes | K9: 0.5 | L9: =I9*K9 -> 2208 | M9: =I9-L9 -> 2208 | N9: Booked in VIkas | P9: DCO2501292 | W9: 8618.34 | Y9: 353.61
A10: 45579 | B10: Mitesh | C10: MSDT | D10: Inspire Group | E10: Managed services | F10: Managed Services | G10: 79600 | H10: 1 | I10: =H10*G10 -> 79600 | J10: Yes | K10: 0.7 | L10: 20800 | M10: 58800 | N10: Booked in VIkas | P10: DMT2500101 | W10: 39900 | X10: 39900 | Y10: 29400 | BA10: 45778
A11: 45691 | B11: Mitesh | C11: MSDT | D11: Atlantis | E11: Back to back support +Support (Onsite) | F11: Managed Services | G11: 498130 | H11: 0.39 | I11: =H11*G11 -> 194270.7 | J11: Yes | K11: 0.7 | L11: =I11*K11 -> 135989.49 | M11: 68557 | N11: Booked in VIkas | P11: DCO2504881 & DMT2500163 | Q11: 12500 | R11: 12500 | S11: 3750 | T11: 11798 | U11: 8258 | V11: 350 | W11: 13062 | X11: 13062 | Y11: 3919 | Z11: =12500*2 -> 25000 | AA11: =12500*2 -> 25000 | AB11: =3750*2 -> 7500 | BA11: 45901
A12: 45714 | B12: Mitesh | C12: MSDT | D12: Safanad | E12: Incident pack - Network | F12: Managed Services | G12: 50000 | H12: 1 | I12: =H12*G12 -> 50000 | J12: Yes | K12: 0.7 | L12: =I12*K12 -> 35000 | M12: 22000 | N12: Booked in VIkas | P12: DMT2500099 | Q12: 4167 | R12: 4167 | S12: 1833.33 | T12: 3836 | U12: 3836 | V12: 1688 | W12: 4379 | X12: 4379 | Y12: 1999 | BA12: 45778
A13: 45714 | B13: Mitesh | C13: MSDT | D13: Safanad | E13: Managed services - End user support | F13: Managed Services | G13: 33000 | H13: 1 | I13: =H13*G13 -> 33000 | J13: Yes | K13: 0.7 | L13: =I13*K13 -> 23100 | M13: 15500 | N13: Booked in VIkas | P13: DMT2500086 | Q13: 2750 | R13: 2750 | S13: 1291.67 | T13: 2532 | U13: 2532 | V13: 1190 | W13: 2802 | X13: 2802 | Y13: 1312 | BA13: 45778
A14: 45770 | B14: Mitesh | C14: MSDT | D14: KARM Advisory Management Consultancy LLC | E14: Managed Services | F14: Managed Services | G14: 60000 | H14: 1 | I14: =H14*G14 -> 60000 | J14: Yes | K14: 0.7 | L14: 36400 | M14: 23600 | N14: Booked in VIkas | P14: DMT2500124 | Q14: 5000 | R14: 5000 | S14: 1966.67 | T14: 4551 | U14: 4551 | V14: 1688 | W14: 5225 | X14: 5225 | Y14: 2056 | Z14: 5000 | AA14: 5000 | AB14: 1966.67
A15: 45782 | B15: Mitesh | C15: Micro | D15: Sukoon Insurance | E15: VDI Citrix AMC | F15: Micro | G15: 78000 | H15: 1 | I15: =H15*G15 -> 78000 | J15: Yes | K15: 0.5 | L15: =I15*K15 -> 39000 | M15: =I15-L15 -> 39000 | O15: 46082 | P15: DMT2500149 | Q15: 6500 | R15: 6500 | S15: 3250 | T15: 5982 | U15: 2994 | V15: 2988 | W15: 6500 | X15: 6500 | Y15: 3250
A16: 45770 | B16: Mitesh | C16: MSDT | D16: KARM Advisory Management Consultancy LLC | E16: AIP for Data Protection | F16: Managed Services | G16: 30000 | H16: 1 | I16: =H16*G16 -> 30000 | J16: Yes | K16: 0.7 | L16: 7500 | M16: 22500 | N16: Booked in VIkas | P16: DCO2503504 | AC16: 30000 | AD16: 30000 | AE16: 22500
A17: 45422 | B17: Mitesh | C17: MSDT | D17: OilMar | E17: Migration - M365 / Azure | F17: Microsoft | G17: 221793 | H17: 0.83 | I17: =H17*G17 -> 184088.19 | J17: Yes | K17: 0.5 | L17: 111232.19 | M17: 72856 | N17: Booked in VIkas | P17: DCO2502558 | Z17: 57500 | AA17: 57500 | AB17: 28750
A18: 45470 | B18: Mitesh | C18: MSDT | D18: OilMar | E18: Security tools & Services | F18: Cybersecurity | G18: 60000 | H18: 1 | I18: =H18*G18 -> 60000 | J18: Yes | K18: 0.7 | L18: =I18*K18 -> 42000 | M18: 32000 | N18: Booked in VIkas | P18: DCO2502566 | Z18: 36000 | AA18: 36000 | AB18: 19200
A19: 45616 | B19: Mitesh | C19: MSDT | D19: Hutchison Ajman International Terminals | E19: Fortinac licences & implementation | F19: Cybersecurity | G19: 161428 | H19: 0.1 | I19: =H19*G19 -> 16142.8 | J19: Yes | K19: 0.7 | L19: =I19*K19 -> 11299.96 | M19: 8071.4 | N19: Booked in VIkas | P19: DCO2500019, DCO2500057, DCO2500060, DCO2500061 | AC19: 61948 | AD19: 58970 | AE19: 2977.54 | AF19: 80714 | AG19: 8071 | AH19: 8071.4
A20: 45790 | B20: Mitesh | C20: MSDT | D20: Hutchison Ajman | E20: Infra Managed services | F20: Managed Services | G20: 289200 | H20: 1 | I20: =H20*G20 -> 289200 | J20: Yes | K20: 0.7 | L20: 220200 | M20: 69000 | O20: 46082 | P20: DMT2500220, DMT2500221, DMT2500226, DMT2500227 & DMT2500228 | T20: =24100+48200 -> 72300 | U20: =19000+38000 -> 57000 | V20: 37133 | W20: 13399 | X20: =W20-1560 -> 11839 | Y20: 11839 | Z20: 24100 | AA20: 15416 | AB20: 1285 | AC20: 24100 | AD20: 15416 | AE20: 1285 | AF20: 24100 | AG20: 15416 | AH20: 1285 | AI20: 24100 | AJ20: 15416 | AK20: 1285 | AL20: 24100 | AM20: 15416 | AN20: 1285
A21: 45840 | B21: Mitesh | C21: MSDT | D21: Hutchison Ajman | E21: Oracle forms & PL/SQL development project (10 months) - Rafey | F21: Other Application | G21: 180960 | H21: 1 | I21: =H21*G21 -> 180960 | J21: Yes | K21: 0.8 | L21: 155500 | M21: 25460 | O21: 46113 | P21: DCO2506438 | T21: 54288 | U21: 7788 | V21: 7788 | AC21: 54288 | AD21: 7788 | AE21: 7788 | AF21: 54288 | AG21: 7788 | AH21: 7788 | AI21: 18096 | AJ21: 15500 | AK21: 2596 | AL21: 18096 | AM21: 15500 | AN21: 2596
A22: 45840 | B22: Mitesh | C22: MSDT | D22: Hutchison Ajman | E22: 12 digit HS Code CR | F22: Other Application | G22: 34000 | H22: 0.38 | I22: =H22*G22 -> 12920 | J22: No | K22: 0.5 | L22: =I22*K22 -> 6460 | M22: 6460 | N22: Booked in VIkas | O22: 46054 | P22: DCO2507602 | Q22: 34000 | R22: 22500 | S22: 6460
B23: Mitesh | C23: MSDT | D23: Hutchison Logistics (Ajman Customs) | E23: OCR / RPA to automate the documentation process | F23: Other Application | G23: 250500 | H23: 0.62 | I23: =H23*G23 -> 155310 | J23: No | K23: 0.5 | L23: =I23*K23 -> 77655 | M23: 77655 | P23: DCO2308808
A24: 45818 | B24: Mitesh | C24: MSDT | D24: Akhdar Trading | E24: MDR Support | F24: Cybersecurity | G24: 36000 | H24: 0.67 | I24: =H24*G24 -> 24120 | J24: No | K24: 0.5 | L24: 24000 | M24: 12000 | P24: DMT2500001 | T24: =3000+6000 -> 9000 | U24: =2000+4000 -> 6000 | V24: 5084 | Y24: -6013.12
A25: 45818 | B25: Mitesh | C25: MSDT | D25: EANAN Drones | E25: MDR Support | F25: Cybersecurity | G25: 35000 | H25: 0.66 | I25: =H25*G25 -> 23100 | J25: No | K25: 0.5 | L25: 23250 | M25: 11750 | P25: DMT2400310 | T25: =2916.5+5833.33 -> 8749.83 | U25: =1937.5+3875 -> 5812.5 | V25: 4939 | Y25: -5748.16
A26: 45818 | B26: Mitesh | C26: MSDT | D26: Sustainable Food Supplies | E26: MDR Support | F26: Cybersecurity | G26: 34500 | H26: 0.67 | I26: =H26*G26 -> 23115 | J26: No | K26: 0.5 | L26: 23000 | M26: 11500 | P26: DMT2400312 | T26: =2875+5750 -> 8625 | U26: =1916.66+2875 -> 4791.66 | V26: 7750 | Y26: -8623
A27: 45818 | B27: Mitesh | C27: MSDT | D27: Green suppliers group companies | E27: MDR Support | F27: Cybersecurity | G27: 5100 | H27: 0.68 | I27: =H27*G27 -> 3468 | J27: No | K27: 0.5 | L27: 3400 | M27: 1700 | P27: DMT2400311 | T27: =425+850 -> 1275 | U27: 1000 | V27: 724 | Y27: -839.04
A28: 45877 | B28: Mitesh | C28: MSDT | D28: Hutchison Ajman | E28: AD migration | F28: Managed Services | G28: 6950 | H28: 1 | I28: =H28*G28 -> 6950 | J28: Yes | K28: 0.7 | L28: =I28*K28 -> 4865 | M28: =I28-L28 -> 2085 | O28: 46023 | P28: DCO2506767 | AC28: 6950 | AD28: 6950 | AE28: 2085
A29: 45967 | B29: Mitesh | C29: NW | D29: Crescent Petroleum | E29: Palo Alto Renewal | F29: Network | G29: 72445 | H29: 0.1 | I29: =H29*G29 -> 7244.5 | J29: No | K29: 0.5 | L29: =I29*K29 -> 3622.25 | M29: =I29-L29 -> 3622.25 | O29: 46054 | P29: DCO2509214 | T29: 72445.82 | U29: 4045.6 | V29: 4045.6
B30: Mitesh | C30: Micro | D30: Oilmar | E30: Dynamics - Renewal | F30: Micro | G30: 131098 | H30: 0.182 | I30: =H30*G30 -> 23859.836 | J30: Yes | K30: 0.5 | L30: =I30*K30 -> 11929.918 | M30: =I30-L30 -> 11929.918 | O30: 46113 | P30: DCO2510031 | W30: 131098 | X30: 18353.72 | Y30: 11936.51
B31: Mitesh | C31: NW | D31: Safanad | E31: Services - network | F31: Network | G31: 14500 | H31: 1 | I31: =H31*G31 -> 14500 | J31: Yes | K31: 0.5 | L31: =I31*K31 -> 7250 | M31: =I31-L31 -> 7250 | O31: 46143 | P31: DCO2600119 | Z31: 14500 | AA31: 14500 | AB31: 10250
B32: Mitesh | C32: MSDT | D32: KARM Advisory Management Consultancy LLC | E32: MDR Services | F32: Cybersecurity | G32: 33000 | I32: =H32*G32 -> 0 | L32: =I32*K32 -> 0 | M32: =I32-L32 -> 0 | P32: DMT2500125 | T32: 8250 | V32: 5687
B33: Mitesh | C33: Micro | D33: Sukoon Insurance | E33: Dell VXRAIL (2025) - Pending to be billed | F33: Micro | G33: 52000 | H33: 1 | I33: =H33*G33 -> 52000 | J33: Yes | K33: 0.5 | L33: =I33*K33 -> 26000 | M33: =I33-L33 -> 26000 | P33: DCO2500343 | AC33: 52000 | AD33: 17500 | AE33: 8750
B34: Mitesh | C34: Micro | D34: Sukoon Insurance | E34: Micro tasks transfer from Raj | F34: Micro | G34: 87000 | H34: 1 | I34: =H34*G34 -> 87000 | J34: Yes | K34: 0.5 | L34: =I34*K34 -> 43500 | M34: =I34-L34 -> 43500 | O34: 46054 | S34: 43500
B35: Mitesh | C35: Micro | D35: Larsen Global | E35: Microsoft Licences | F35: Micro | G35: 84520 | H35: 0.2075891 | I35: =H35*G35 -> 17545.431 | K35: 0.5 | L35: =I35*K35 -> 8772.7154 | M35: =I35-L35 -> 8772.7154 | O35: 46054 | P35: DCO2509644 | Q35: 84520.8 | R35: 17545.6 | S35: 8772.8
B36: Mitesh | C36: NW | D36: Hutchison Ajman | E36: Fortinet - Renewal (Refresh Project) | F36: Network | G36: 21000 | H36: 0.05 | I36: 1881.08 | K36: 0.5 | L36: =I36*K36 -> 940.54 | M36: =I36-L36 -> 940.54 | O36: 46054 | P36: DCO2510060 | Q36: 21000 | R36: 1881.08 | S36: 940.54
B37: Mitesh | C37: Micro | D37: EANAN Drones & Group companies | E37: Consolidated orders | F37: Micro | G37: 12822.41 | H37: 0.188764 | I37: =H37*G37 -> 2420.4094 | K37: 0.5 | L37: =I37*K37 -> 1210.2047 | M37: =I37-L37 -> 1210.2047 | O37: 46054 | P37: DCO2508573, DCO2600240, DCO2509572 | Q37: 12822.41 | R37: 2420.41 | S37: 1210.2
B38: Mitesh | C38: MSDT | D38: Teleperformance | E38: Managed Services - UAE | F38: Managed Services | G38: 222000 | H38: 1 | I38: =H38*G38 -> 222000 | J38: Yes | K38: 0.7 | L38: =I38*K38 -> 155400 | M38: =I38-L38 -> 66600 | O38: 46143 | P38: DMT2600001 & DMT2600002 | Q38: 45848 | R38: 45848 | S38: 18273 | T38: 9652 | U38: 9652 | V38: -1624
B39: Mitesh | C39: MSDT | D39: Sukoon Insurance | E39: Veritas AMC | F39: Managed Services | G39: 48000 | H39: 0.2716 | I39: =H39*G39 -> 13036.8 | J39: Yes | K39: 0.5 | L39: =I39*K39 -> 6518.4 | M39: =I39-L39 -> 6518.4 | O39: 46143 | P39: DMT2500293 | T39: 7627 | U39: 3967 | V39: 3660 | W39: 4077 | X39: 4077 | Y39: 278 | Z39: 4000 | AA39: 1086.4 | AB39: 543.2 | AC39: 4000 | AD39: 1086.4 | AE39: 543.2 | AF39: 4000 | AG39: 1086.4 | AH39: 543.2 | AI39: 4000 | AJ39: 1086.4 | AK39: 543.2 | AL39: 4000 | AM39: 1086.4 | AN39: 543.2 | AO39: 4000 | AP39: 1086.4 | AQ39: 543.2 | AR39: 4000 | AS39: 1086.4 | AT39: 543.2 | AU39: 4000 | AV39: 1086.4 | AW39: 543.2 | AX39: 4000 | AY39: 1086.4 | AZ39: 543.2
B40: Mitesh | C40: Micro | D40: Sukoon Insurance | E40: Dell VXRAIL (2025-26) | F40: Micro | G40: 120000 | H40: 1 | I40: =H40*G40 -> 120000 | J40: Yes | K40: 0.5 | L40: =I40*K40 -> 60000 | M40: =I40-L40 -> 60000
...

Sheet Opportunity Tracker
A1: Porposal Date | B1: Account Manager | C1: Presales | D1: Customer | E1: Project Description | F1: Division | G1: Project Type | H1: Proposal Value | I1: GP% | J1: GP Value | K1: NP Value | L1: Status | M1: Tentative month of closure | N1: Billing in 2026
B2: Mitesh | C2: Rishabh | D2: Teleperformance | E2: Managed Services (KSA) | F2: MSDT | G2: Managed Services | H2: 325000 | I2: 1 | J2: =H2*I2 -> 325000 | K2: =J2*50% -> 162500 | L2: 0.5
B3: Mitesh | C3: Muthu | D3: Hutchison | E3: Environment Monitoring System | F3: ELV | G3: ELV | H3: 104122 | I3: 0.2 | J3: =H3*I3 -> 20824.4 | K3: =J3*50% -> 10412.2 | L3: 0.8 | M3: April | N3: 100% Billing in 2026
B4: Mitesh | C4: Saud | D4: Kotak Mahindra | E4: New office set up project | F4: NW | G4: Network | H4: 646687 | I4: 0.15 | J4: =H4*I4 -> 97003.05 | K4: =J4*50% -> 48501.525 | L4: 0.8 | M4: June | N4: 100% Billing in 2026
B5: Mitesh | C5: Saud | D5: Safanad | E5: Network Support | F5: MSDT | G5: Managed Services | H5: 40000 | I5: 1 | J5: =H5*I5 -> 40000 | K5: =J5*50% -> 20000 | L5: 0.5
B6: Mitesh | C6: Rishabh | D6: Safanad | E6: End user support | F6: MSDT | G6: Managed Services | H6: 36000 | I6: 1 | J6: =H6*I6 -> 36000 | K6: =J6*50% -> 18000 | L6: 0.5
B7: Mitesh | C7: Muthu | D7: Emirates Transport | E7: Data center | F7: ELV | G7: ELV | H7: 153902 | I7: 0.2 | J7: =H7*I7 -> 30780.4 | K7: =J7/2 -> 15390.2 | L7: 0.5 | M7: 46143
B8: Mitesh | C8: Muthu | D8: Nestle | E8: ELV requirement - Board room | F8: ELV | G8: ELV | H8: 58373 | I8: 0.15 | J8: =H8*I8 -> 8755.95 | K8: =J8*50% -> 4377.975 | L8: 0.5
B9: Mitesh | C9: Mohan | D9: Hutchison Ajman | E9: Server support | F9: Micro | G9: Micro | H9: 43500 | I9: 1 | J9: =H9*I9 -> 43500 | K9: =J9*50% -> 21750 | L9: 0.5
B10: Mitesh | C10: Mohan | D10: Sukoon | E10: AD Upgrade | F10: Micro | G10: Micro | H10: 78500 | I10: 1 | J10: =H10*I10 -> 78500 | K10: =J10*50% -> 39250 | L10: 0.5
B11: Mitesh | C11: Mohan | D11: Mudhrastrec | E11: AD Migration | F11: Micro | G11: Micro | H11: 145000 | I11: 1 | J11: =H11*I11 -> 145000 | K11: =J11*50% -> 72500 | L11: 0.5
B12: Mitesh | C12: Rishabh | D12: Mudhrastrec | E12: Security+Managed services | F12: MSDT | G12: Managed Services | H12: 277000 | I12: 1 | J12: =H12*I12 -> 277000 | K12: =J12*50% -> 138500 | L12: 0.5
B13: Mitesh | C13: Kumar | D13: Ajman Municipality & Planning | E13: Veeam support renewal | F13: Micro | G13: Micro | H13: 1408436.9 | I13: 0.07 | J13: =H13*I13 -> 98590.583 | K13: =J13*50% -> 49295.291 | L13: 0.5
B14: Mitesh | C14: Saud | D14: Hutchison | E14: Firewall Refresh project | F14: NW | G14: Network | H14: 522406 | I14: 0.12 | J14: =H14*I14 -> 62688.72 | K14: =J14*50% -> 31344.36 | L14: 0.8 | M14: May | N14: 100% Billing in 2026
B15: Mitesh | C15: Saud | D15: Kotak Mahindra | E15: Refresh - EOL | F15: NW | G15: Network | H15: 225000 | I15: 0.25 | J15: =H15*I15 -> 56250 | K15: =J15*50% -> 28125 | L15: 0.8
B16: Mitesh | C16: Saud | D16: Fakeeh University Hospital | E16: F5 Renewal | F16: NW | G16: Network | H16: 276509 | I16: 0.1 | J16: =H16*I16 -> 27650.9 | K16: =J16 -> 27650.9 | L16: 0.5
B17: Mitesh | C17: Mohan | D17: Sukoon Insurance | E17: AD Migration | F17: Micro | G17: Micro | H17: 80000 | I17: 1 | J17: =H17*I17 -> 80000 | K17: 40000 | L17: 0.5 | M17: May
B18: Mitesh | C18: Rishabh | D18: Atlantis the Palm | E18: NOC Support + Back to back renewals | F18: NW | G18: Network | H18: 498130 | I18: 0.2 | J18: =H18*I18 -> 99626 | K18: =J18/2 -> 49813 | L18: 0.5
B19: Mitesh | C19: Mohan | D19: Fakeeh University Hospital | E19: F5 Renewal | F19: NW | G19: Network | H19: 276509 | I19: 0.1 | J19: =H19*I19 -> 27650.9 | K19: =J19 -> 27650.9 | L19: 0.5
B20: Mitesh | C20: Mohan | D20: BMS Masaood Insurance LLC | E20: Infrastructure set up | F20: Micro | G20: Micro | H20: 453757 | I20: 0.2 | J20: =H20*I20 -> 90751.4 | K20: =J20/2 -> 45375.7 | L20: 0.5
B21: Mitesh | C21: Muthu | D21: Emirates Transport | E21: Incident Pack | F21: ELV | G21: ELV | H21: 85000 | I21: 1 | J21: =H21*I21 -> 85000 | K21: =J21/2 -> 42500 | L21: 0.5
B22: Mitesh | C22: Rishabh | D22: Green Suppliers & Group companies | E22: Managed Services | F22: MSDT | G22: Managed Services | H22: 144000 | I22: 1 | J22: =H22*I22 -> 144000 | K22: =J22*50% -> 72000 | L22: 0.5
